Workbook

Sheet README
A1: JOPACC Payment Systems Monthly Report — Consolidated Dataset
A3: Source: extracted data from JOPACC monthly Payment Systems Report PDFs (Sep 2024 – Aug 2026).
A5: Sheets in this workbook:
A6: • CliQ - instant/person-to-person payments (users + transactions)
A7: • JoMoPay - mobile wallet payments (users + transactions)
A8: • eFAWATEERcom - bill payment platform (users + transactions by biller)
A9: • ACH - Automated Clearing House (JOD + foreign-currency transactions)
A10: • ECCU - Electronic Cheque Clearing Unit (cheques + returned cheques)
A11: • Interoperability - cross-system / cross-institution money-transfer flows
A12: • Instant Payments - bank-account vs mobile-wallet instant payment channel (partial history)
A13: • Summary - monthly headline totals (users, transactions) side-by-side across systems
A15: Layout:
... A39: • Cells that were blank in the original stay blank (no formula), so a month with no source data is not shown as 0.

Sheet CliQ
A1: CliQ (Instant Payments)
A2: Raw Data keys → (system | period) | B2: cliq | C2: =RIGHT(C$3,4)&"-"&TEXT(MATCH(LEFT(C$3,3),{"Jan","Feb","Mar","Apr","May","Jun","Jul","Aug","Sep","Oct","Nov","Dec"},0),"00") -> 2024-09 | D2: =RIGHT(D$3,4)&"-"&TEXT(MATCH(LEFT(D$3,3),{"Jan","Feb","Mar","Apr","May","Jun","Jul","Aug","Sep","Oct","Nov","Dec"},0),"00") -> 2024-10 | E2: =RIGHT(E$3,4)&"-"&TEXT(MATCH(LEFT($E3,3),{"Jan","Feb","Mar","Apr","May","Jun","Jul","Aug","Sep","Oct","Nov","Dec"},0),"00") -> 2024-11 | F2: =RIGHT(F$3,4)&"-"&TEXT(MATCH(LEFT(F$3,3),{"Jan","Feb","Mar","Apr","May","Jun","Jul","Aug","Sep","Oct","Nov","Dec"},0),"00") -> 2024-12 | G2: =RIGHT(G$3,4)&"-"&TEXT(MATCH(LEFT(G$3,3),{"Jan","Feb","Mar","Apr","May","Jun","Jul","Aug","Sep","Oct","Nov","Dec"},0),"00") -> 2025-01 | H2: =RIGHT(H$3,4)&"-"&TEXT(MATCH(LEFT(H$3,3),{"Jan","Feb","Mar","Apr","May","Jun","Jul","Aug","Sep","Oct","Nov","Dec"},0),"00") -> 2025-02 | I2: =RIGHT(I$3,4)&"-"&TEXT(MATCH(LEFT(I$3,3),{"Jan","Feb","Mar","Apr","May","Jun","Jul","Aug","Sep","Oct","Nov","Dec"},0),"00") -> 2025-03 | J2: =RIGHT(J$3,4)&"-"&TEXT(MATCH(LEFT(J$3,3),{"Jan","Feb","Mar","Apr","May","Jun","Jul","Aug","Sep","Oct","Nov","Dec"},0),"00") -> 2025-04 | K2: =RIGHT(K$3,4)&"-"&TEXT(MATCH(LEFT(K$3,3),{"Jan","Feb","Mar","Apr","May","Jun","Jul","Aug","Sep","Oct","Nov","Dec"},0),"00") -> 2025-05 | L2: =RIGHT(L$3,4)&"-"&TEXT(MATCH(LEFT(L$3,3),{"Jan","Feb","Mar","Apr","May","Jun","Jul","Aug","Sep","Oct","Nov","Dec"},0),"00") -> 2025-06 | M2: =RIGHT(M$3,4)&"-"&TEXT(MATCH(LEFT(M$3,3),{"Jan","Feb","Mar","Apr","May","Jun","Jul","Aug","Sep","Oct","Nov","Dec"},0),"00") -> 2025-07 | ... Z2: =RIGHT(Z$3,4)&"-"&TEXT(MATCH(LEFT(Z$3,3),{"Jan","Feb","Mar","Apr","May","Jun","Jul","Aug","Sep","Oct","Nov","Dec"},0),"00") -> 2026-08
A3: Category | B3: Metric | C3: Sep 2024 | D3: Oct 2024 | E3: Nov 2024 | F3: Dec 2024 | G3: Jan 2025 | H3: Feb 2025 | I3: Mar 2025 | J3: Apr 2025 | K3: May 2025 | L3: Jun 2025 | M3: Jul 2025 | N3: Aug 2025 | O3: Sep 2025 | P3: Oct 2025 | Q3: Nov 2025 | R3: Dec 2025 | S3: Jan 2026 | T3: Feb 2026 | U3: Mar 2026 | V3: Apr 2026 | W3: May 2026 | X3: Jun 2026 | Y3: Jul 2026 | Z3: Aug 2026
A4: USERS BY NATIONALITY (Number)
A5: Users | B5: Jordanian | C5: =SUMIFS('Raw Data'!$L:$L,'Raw Data'!$B:$B,$B$2,'Raw Data'!$J:$J,C$2,'Raw Data'!$K:$K,"native",'Raw Data'!$H:$H,"Jordanian",'Raw Data'!$I:$I,"",'Raw Data'!$M:$M,"count") -> 1500000 | D5: =SUMIFS('Raw Data'!$L:$L,'Raw Data'!$B:$B,$B$2,'Raw Data'!$J:$J,D$2,'Raw Data'!$K:$K,"native",'Raw Data'!$H:$H,"Jordanian",'Raw Data'!$I:$I,"",'Raw Data'!$M:$M,"count") -> 1540000 | E5: =SUMIFS('Raw Data'!$L:$L,'Raw Data'!$B:$B,$B$2,'Raw Data'!$J:$J,E$2,'Raw Data'!$K:$K,"native",'Raw Data'!$H:$H,"Jordanian",'Raw Data'!$I:$I,"",'Raw Data'!$M:$M,"count") -> 1570000 | F5: =SUMIFS('Raw Data'!$L:$L,'Raw Data'!$B:$B,$B$2,'Raw Data'!$J:$J,F$2,'Raw Data'!$K:$K,"native",'Raw Data'!$H:$H,"Jordanian",'Raw Data'!$I:$I,"",'Raw Data'!$M:$M,"count") -> 1610000 | G5: =SUMIFS('Raw Data'!$L:$L,'Raw Data'!$B:$B,$B$2,'Raw Data'!$J:$J,G$2,'Raw Data'!$K:$K,"native",'Raw Data'!$H:$H,"Jordanian",'Raw Data'!$I:$I,"",'Raw Data'!$M:$M,"count") -> 1640000 | H5: =SUMIFS('Raw Data'!$L:$L,'Raw Data'!$B:$B,$B$2,'Raw Data'!$J:$J,H$2,'Raw Data'!$K:$K,"native",'Raw Data'!$H:$H,"Jordanian",'Raw Data'!$I:$I,"",'Raw Data'!$M:$M,"count") -> 1680000 | I5: =SUMIFS('Raw Data'!$L:$L,'Raw Data'!$B:$B,$B$2,'Raw Data'!$J:$J,I$2,'Raw Data'!$K:$K,"native",'Raw Data'!$H:$H,"Jordanian",'Raw Data'!$I:$I,"",'Raw Data'!$M:$M,"count") -> 1710000 | J5: =SUMIFS('Raw Data'!$L:$L,'Raw Data'!$B:$B,$B$2,'Raw Data'!$J:$J,J$2,'Raw Data'!$K:$K,"native",'Raw Data'!$H:$H,"Jordanian",'Raw Data'!$I:$I,"",'Raw Data'!$M:$M,"count") -> 1750000 | ... Z5: =SUMIFS('Raw Data'!$L:$L,'Raw Data'!$B:$B,$B$2,'Raw Data'!$J:$J,Z$2,'Raw Data'!$K:$K,"native",'Raw Data'!$H:$H,"Jordanian",'Raw Data'!$I:$I,"",'Raw Data'!$M:$M,"count") -> 2290000
A6: Users | B6: Non-Jordanian | C6: =SUMIFS('Raw Data'!$L:$L,'Raw Data'!$B:$B,$B$2,'Raw Data'!$J:$J,C$2,'Raw Data'!$K:$K,"native",'Raw Data'!$H:$H,"Non-Jordanian",'Raw Data'!$I:$I,"",'Raw Data'!$M:$M,"count") -> 55000 | D6: =SUMIFS('Raw Data'!$L:$L,'Raw Data'!$B:$B,$B$2,'Raw Data'!$J:$J,D$2,'Raw Data'!$K:$K,"native",'Raw Data'!$H:$H,"Non-Jordanian",'Raw Data'!$I:$I,"",'Raw Data'!$M:$M,"count") -> 57000 | E6: =SUMIFS('Raw Data'!$L:$L,'Raw Data'!$B:$B,$B$2,'Raw Data'!$J:$J,E$2,'Raw Data'!$K:$K,"native",'Raw Data'!$H:$H,"Non-Jordanian",'Raw Data'!$I:$I,"",'Raw Data'!$M:$M,"count") -> 59000 | F6: =SUMIFS('Raw Data'!$L:$L,'Raw Data'!$B:$B,$B$2,'Raw Data'!$J:$J,F$2,'Raw Data'!$K:$K,"native",'Raw Data'!$H:$H,"Non-Jordanian",'Raw Data'!$I:$I,"",'Raw Data'!$M:$M,"count") -> 61000 | G6: =SUMIFS('Raw Data'!$L:$L,'Raw Data'!$B:$B,$B$2,'Raw Data'!$J:$J,G$2,'Raw Data'!$K:$K,"native",'Raw Data'!$H:$H,"Non-Jordanian",'Raw Data'!$I:$I,"",'Raw Data'!$M:$M,"count") -> 63000 | H6: =SUMIFS('Raw Data'!$L:$L,'Raw Data'!$B:$B,$B$2,'Raw Data'!$J:$J,H$2,'Raw Data'!$K:$K,"native",'Raw Data'!$H:$H,"Non-Jordanian",'Raw Data'!$I:$I,"",'Raw Data'!$M:$M,"count") -> 65000 | I6: =SUMIFS('Raw Data'!$L:$L,'Raw Data'!$B:$B,$B$2,'Raw Data'!$J:$J,I$2,'Raw Data'!$K:$K,"native",'Raw Data'!$H:$H,"Non-Jordanian",'Raw Data'!$I:$I,"",'Raw Data'!$M:$M,"count") -> 67000 | J6: =SUMIFS('Raw Data'!$L:$L,'Raw Data'!$B:$B,$B$2,'Raw Data'!$J:$J,J$2,'Raw Data'!$K:$K,"native",'Raw Data'!$H:$H,"Non-Jordanian",'Raw Data'!$I:$I,"",'Raw Data'!$M:$M,"count") -> 68300 | ... Z6: =SUMIFS('Raw Data'!$L:$L,'Raw Data'!$B:$B,$B$2,'Raw Data'!$J:$J,Z$2,'Raw Data'!$K:$K,"native",'Raw Data'!$H:$H,"Non-Jordanian",'Raw Data'!$I:$I,"",'Raw Data'!$M:$M,"count") -> 98600
A7: USERS BY GENDER (Number)
A8: Users | B8: Female Users | C8: =SUMIFS('Raw Data'!$L:$L,'Raw Data'!$B:$B,$B$2,'Raw Data'!$J:$J,C$2,'Raw Data'!$K:$K,"native",'Raw Data'!$H:$H,"Female*",'Raw Data'!$I:$I,"",'Raw Data'!$M:$M,"count") -> 541300 | D8: =SUMIFS('Raw Data'!$L:$L,'Raw Data'!$B:$B,$B$2,'Raw Data'!$J:$J,D$2,'Raw Data'!$K:$K,"native",'Raw Data'!$H:$H,"Female*",'Raw Data'!$I:$I,"",'Raw Data'!$M:$M,"count") -> 556500 | E8: =SUMIFS('Raw Data'!$L:$L,'Raw Data'!$B:$B,$B$2,'Raw Data'!$J:$J,E$2,'Raw Data'!$K:$K,"native",'Raw Data'!$H:$H,"Female*",'Raw Data'!$I:$I,"",'Raw Data'!$M:$M,"count") -> 570000 | F8: =SUMIFS('Raw Data'!$L:$L,'Raw Data'!$B:$B,$B$2,'Raw Data'!$J:$J,F$2,'Raw Data'!$K:$K,"native",'Raw Data'!$H:$H,"Female*",'Raw Data'!$I:$I,"",'Raw Data'!$M:$M,"count") -> 580000 | G8: =SUMIFS('Raw Data'!$L:$L,'Raw Data'!$B:$B,$B$2,'Raw Data'!$J:$J,G$2,'Raw Data'!$K:$K,"native",'Raw Data'!$H:$H,"Female*",'Raw Data'!$I:$I,"",'Raw Data'!$M:$M,"count") -> 600000 | H8: =SUMIFS('Raw Data'!$L:$L,'Raw Data'!$B:$B,$B$2,'Raw Data'!$J:$J,H$2,'Raw Data'!$K:$K,"native",'Raw Data'!$H:$H,"Female*",'Raw Data'!$I:$I,"",'Raw Data'!$M:$M,"count") -> 610000 | I8: =SUMIFS('Raw Data'!$L:$L,'Raw Data'!$B:$B,$B$2,'Raw Data'!$J:$J,I$2,'Raw Data'!$K:$K,"native",'Raw Data'!$H:$H,"Female*",'Raw Data'!$I:$I,"",'Raw Data'!$M:$M,"count") -> 620000 | J8: =SUMIFS('Raw Data'!$L:$L,'Raw Data'!$B:$B,$B$2,'Raw Data'!$J:$J,J$2,'Raw Data'!$K:$K,"native",'Raw Data'!$H:$H,"Female*",'Raw Data'!$I:$I,"",'Raw Data'!$M:$M,"count") -> 640000 | ... Z8: =SUMIFS('Raw Data'!$L:$L,'Raw Data'!$B:$B,$B$2,'Raw Data'!$J:$J,Z$2,'Raw Data'!$K:$K,"native",'Raw Data'!$H:$H,"Female*",'Raw Data'!$I:$I,"",'Raw Data'!$M:$M,"count") -> 870000
A9: Users | B9: Male Users | C9: =SUMIFS('Raw Data'!$L:$L,'Raw Data'!$B:$B,$B$2,'Raw Data'!$J:$J,C$2,'Raw Data'!$K:$K,"native",'Raw Data'!$H:$H,"Male*",'Raw Data'!$I:$I,"",'Raw Data'!$M:$M,"count") -> 973400 | D9: =SUMIFS('Raw Data'!$L:$L,'Raw Data'!$B:$B,$B$2,'Raw Data'!$J:$J,D$2,'Raw Data'!$K:$K,"native",'Raw Data'!$H:$H,"Male*",'Raw Data'!$I:$I,"",'Raw Data'!$M:$M,"count") -> 997400 | E9: =SUMIFS('Raw Data'!$L:$L,'Raw Data'!$B:$B,$B$2,'Raw Data'!$J:$J,E$2,'Raw Data'!$K:$K,"native",'Raw Data'!$H:$H,"Male*",'Raw Data'!$I:$I,"",'Raw Data'!$M:$M,"count") -> 1020000 | F9: =SUMIFS('Raw Data'!$L:$L,'Raw Data'!$B:$B,$B$2,'Raw Data'!$J:$J,F$2,'Raw Data'!$K:$K,"native",'Raw Data'!$H:$H,"Male*",'Raw Data'!$I:$I,"",'Raw Data'!$M:$M,"count") -> 1040000 | G9: =SUMIFS('Raw Data'!$L:$L,'Raw Data'!$B:$B,$B$2,'Raw Data'!$J:$J,G$2,'Raw Data'!$K:$K,"native",'Raw Data'!$H:$H,"Male*",'Raw Data'!$I:$I,"",'Raw Data'!$M:$M,"count") -> 1060000 | H9: =SUMIFS('Raw Data'!$L:$L,'Raw Data'!$B:$B,$B$2,'Raw Data'!$J:$J,H$2,'Raw Data'!$K:$K,"native",'Raw Data'!$H:$H,"Male*",'Raw Data'!$I:$I,"",'Raw Data'!$M:$M,"count") -> 1080000 | I9: =SUMIFS('Raw Data'!$L:$L,'Raw Data'!$B:$B,$B$2,'Raw Data'!$J:$J,I$2,'Raw Data'!$K:$K,"native",'Raw Data'!$H:$H,"Male*",'Raw Data'!$I:$I,"",'Raw Data'!$M:$M,"count") -> 1110000 | J9: =SUMIFS('Raw Data'!$L:$L,'Raw Data'!$B:$B,$B$2,'Raw Data'!$J:$J,J$2,'Raw Data'!$K:$K,"native",'Raw Data'!$H:$H,"Male*",'Raw Data'!$I:$I,"",'Raw Data'!$M:$M,"count") -> 1130000 | ... Z9: =SUMIFS('Raw Data'!$L:$L,'Raw Data'!$B:$B,$B$2,'Raw Data'!$J:$J,Z$2,'Raw Data'!$K:$K,"native",'Raw Data'!$H:$H,"Male*",'Raw Data'!$I:$I,"",'Raw Data'!$M:$M,"count") -> 1450000
A10: USERS BY AGE BRACKET (Number)
A11: Users | B11: 18-30 | C11: =SUMIFS('Raw Data'!$L:$L,'Raw Data'!$B:$B,$B$2,'Raw Data'!$J:$J,C$2,'Raw Data'!$K:$K,"native",'Raw Data'!$H:$H,"18-30",'Raw Data'!$I:$I,"",'Raw Data'!$M:$M,"count") -> 591000 | D11: =SUMIFS('Raw Data'!$L:$L,'Raw Data'!$B:$B,$B$2,'Raw Data'!$J:$J,D$2,'Raw Data'!$K:$K,"native",'Raw Data'!$H:$H,"18-30",'Raw Data'!$I:$I,"",'Raw Data'!$M:$M,"count") -> 605000 | E11: =SUMIFS('Raw Data'!$L:$L,'Raw Data'!$B:$B,$B$2,'Raw Data'!$J:$J,E$2,'Raw Data'!$K:$K,"native",'Raw Data'!$H:$H,"18-30",'Raw Data'!$I:$I,"",'Raw Data'!$M:$M,"count") -> 615000 | F11: =SUMIFS('Raw Data'!$L:$L,'Raw Data'!$B:$B,$B$2,'Raw Data'!$J:$J,F$2,'Raw Data'!$K:$K,"native",'Raw Data'!$H:$H,"18-30",'Raw Data'!$I:$I,"",'Raw Data'!$M:$M,"count") -> 626000 | G11: =SUMIFS('Raw Data'!$L:$L,'Raw Data'!$B:$B,$B$2,'Raw Data'!$J:$J,G$2,'Raw Data'!$K:$K,"native",'Raw Data'!$H:$H,"18-30",'Raw Data'!$I:$I,"",'Raw Data'!$M:$M,"count") -> 637000 | H11: =SUMIFS('Raw Data'!$L:$L,'Raw Data'!$B:$B,$B$2,'Raw Data'!$J:$J,H$2,'Raw Data'!$K:$K,"native",'Raw Data'!$H:$H,"18-30",'Raw Data'!$I:$I,"",'Raw Data'!$M:$M,"count") -> 647000 | I11: =SUMIFS('Raw Data'!$L:$L,'Raw Data'!$B:$B,$B$2,'Raw Data'!$J:$J,I$2,'Raw Data'!$K:$K,"native",'Raw Data'!$H:$H,"18-30",'Raw Data'!$I:$I,"",'Raw Data'!$M:$M,"count") -> 657000 | J11: =SUMIFS('Raw Data'!$L:$L,'Raw Data'!$B:$B,$B$2,'Raw Data'!$J:$J,J$2,'Raw Data'!$K:$K,"native",'Raw Data'!$H:$H,"18-30",'Raw Data'!$I:$I,"",'Raw Data'!$M:$M,"count") -> 667000 | ... Z11: =SUMIFS('Raw Data'!$L:$L,'Raw Data'!$B:$B,$B$2,'Raw Data'!$J:$J,Z$2,'Raw Data'!$K:$K,"native",'Raw Data'!$H:$H,"18-30",'Raw Data'!$I:$I,"",'Raw Data'!$M:$M,"count") -> 839000
A12: Users | B12: 31-40 | C12: =SUMIFS('Raw Data'!$L:$L,'Raw Data'!$B:$B,$B$2,'Raw Data'!$J:$J,C$2,'Raw Data'!$K:$K,"native",'Raw Data'!$H:$H,"31-40",'Raw Data'!$I:$I,"",'Raw Data'!$M:$M,"count") -> 409000 | D12: =SUMIFS('Raw Data'!$L:$L,'Raw Data'!$B:$B,$B$2,'Raw Data'!$J:$J,D$2,'Raw Data'!$K:$K,"native",'Raw Data'!$H:$H,"31-40",'Raw Data'!$I:$I,"",'Raw Data'!$M:$M,"count") -> 419000 | E12: =SUMIFS('Raw Data'!$L:$L,'Raw Data'!$B:$B,$B$2,'Raw Data'!$J:$J,E$2,'Raw Data'!$K:$K,"native",'Raw Data'!$H:$H,"31-40",'Raw Data'!$I:$I,"",'Raw Data'!$M:$M,"count") -> 428000 | F12: =SUMIFS('Raw Data'!$L:$L,'Raw Data'!$B:$B,$B$2,'Raw Data'!$J:$J,F$2,'Raw Data'!$K:$K,"native",'Raw Data'!$H:$H,"31-40",'Raw Data'!$I:$I,"",'Raw Data'!$M:$M,"count") -> 438000 | G12: =SUMIFS('Raw Data'!$L:$L,'Raw Data'!$B:$B,$B$2,'Raw Data'!$J:$J,G$2,'Raw Data'!$K:$K,"native",'Raw Data'!$H:$H,"31-40",'Raw Data'!$I:$I,"",'Raw Data'!$M:$M,"count") -> 448000 | H12: =SUMIFS('Raw Data'!$L:$L,'Raw Data'!$B:$B,$B$2,'Raw Data'!$J:$J,H$2,'Raw Data'!$K:$K,"native",'Raw Data'!$H:$H,"31-40",'Raw Data'!$I:$I,"",'Raw Data'!$M:$M,"count") -> 457000 | I12: =SUMIFS('Raw Data'!$L:$L,'Raw Data'!$B:$B,$B$2,'Raw Data'!$J:$J,I$2,'Raw Data'!$K:$K,"native",'Raw Data'!$H:$H,"31-40",'Raw Data'!$I:$I,"",'Raw Data'!$M:$M,"count") -> 466000 | J12: =SUMIFS('Raw Data'!$L:$L,'Raw Data'!$B:$B,$B$2,'Raw Data'!$J:$J,J$2,'Raw Data'!$K:$K,"native",'Raw Data'!$H:$H,"31-40",'Raw Data'!$I:$I,"",'Raw Data'!$M:$M,"count") -> 474000 | ... Z12: =SUMIFS('Raw Data'!$L:$L,'Raw Data'!$B:$B,$B$2,'Raw Data'!$J:$J,Z$2,'Raw Data'!$K:$K,"native",'Raw Data'!$H:$H,"31-40",'Raw Data'!$I:$I,"",'Raw Data'!$M:$M,"count") -> 607000
A13: Users | B13: 41-50 | C13: =SUMIFS('Raw Data'!$L:$L,'Raw Data'!$B:$B,$B$2,'Raw Data'!$J:$J,C$2,'Raw Data'!$K:$K,"native",'Raw Data'!$H:$H,"41-50",'Raw Data'!$I:$I,"",'Raw Data'!$M:$M,"count") -> 267000 | D13: =SUMIFS('Raw Data'!$L:$L,'Raw Data'!$B:$B,$B$2,'Raw Data'!$J:$J,D$2,'Raw Data'!$K:$K,"native",'Raw Data'!$H:$H,"41-50",'Raw Data'!$I:$I,"",'Raw Data'!$M:$M,"count") -> 275000 | E13: =SUMIFS('Raw Data'!$L:$L,'Raw Data'!$B:$B,$B$2,'Raw Data'!$J:$J,E$2,'Raw Data'!$K:$K,"native",'Raw Data'!$H:$H,"41-50",'Raw Data'!$I:$I,"",'Raw Data'!$M:$M,"count") -> 282000 | F13: =SUMIFS('Raw Data'!$L:$L,'Raw Data'!$B:$B,$B$2,'Raw Data'!$J:$J,F$2,'Raw Data'!$K:$K,"native",'Raw Data'!$H:$H,"41-50",'Raw Data'!$I:$I,"",'Raw Data'!$M:$M,"count") -> 289000 | G13: =SUMIFS('Raw Data'!$L:$L,'Raw Data'!$B:$B,$B$2,'Raw Data'!$J:$J,G$2,'Raw Data'!$K:$K,"native",'Raw Data'!$H:$H,"41-50",'Raw Data'!$I:$I,"",'Raw Data'!$M:$M,"count") -> 297000 | H13: =SUMIFS('Raw Data'!$L:$L,'Raw Data'!$B:$B,$B$2,'Raw Data'!$J:$J,H$2,'Raw Data'!$K:$K,"native",'Raw Data'!$H:$H,"41-50",'Raw Data'!$I:$I,"",'Raw Data'!$M:$M,"count") -> 304000 | I13: =SUMIFS('Raw Data'!$L:$L,'Raw Data'!$B:$B,$B$2,'Raw Data'!$J:$J,I$2,'Raw Data'!$K:$K,"native",'Raw Data'!$H:$H,"41-50",'Raw Data'!$I:$I,"",'Raw Data'!$M:$M,"count") -> 312000 | J13: =SUMIFS('Raw Data'!$L:$L,'Raw Data'!$B:$B,$B$2,'Raw Data'!$J:$J,J$2,'Raw Data'!$K:$K,"native",'Raw Data'!$H:$H,"41-50",'Raw Data'!$I:$I,"",'Raw Data'!$M:$M,"count") -> 318000 | ... Z13: =SUMIFS('Raw Data'!$L:$L,'Raw Data'!$B:$B,$B$2,'Raw Data'!$J:$J,Z$2,'Raw Data'!$K:$K,"native",'Raw Data'!$H:$H,"41-50",'Raw Data'!$I:$I,"",'Raw Data'!$M:$M,"count") -> 431000
A14: Users | B14: 51-60 | C14: =SUMIFS('Raw Data'!$L:$L,'Raw Data'!$B:$B,$B$2,'Raw Data'!$J:$J,C$2,'Raw Data'!$K:$K,"native",'Raw Data'!$H:$H,"51-60",'Raw Data'!$I:$I,"",'Raw Data'!$M:$M,"count") -> 163000 | D14: =SUMIFS('Raw Data'!$L:$L,'Raw Data'!$B:$B,$B$2,'Raw Data'!$J:$J,D$2,'Raw Data'!$K:$K,"native",'Raw Data'!$H:$H,"51-60",'Raw Data'!$I:$I,"",'Raw Data'!$M:$M,"count") -> 167000 | E14: =SUMIFS('Raw Data'!$L:$L,'Raw Data'!$B:$B,$B$2,'Raw Data'!$J:$J,E$2,'Raw Data'!$K:$K,"native",'Raw Data'!$H:$H,"51-60",'Raw Data'!$I:$I,"",'Raw Data'!$M:$M,"count") -> 172000 | F14: =SUMIFS('Raw Data'!$L:$L,'Raw Data'!$B:$B,$B$2,'Raw Data'!$J:$J,F$2,'Raw Data'!$K:$K,"native",'Raw Data'!$H:$H,"51-60",'Raw Data'!$I:$I,"",'Raw Data'!$M:$M,"count") -> 177000 | G14: =SUMIFS('Raw Data'!$L:$L,'Raw Data'!$B:$B,$B$2,'Raw Data'!$J:$J,G$2,'Raw Data'!$K:$K,"native",'Raw Data'!$H:$H,"51-60",'Raw Data'!$I:$I,"",'Raw Data'!$M:$M,"count") -> 181000 | H14: =SUMIFS('Raw Data'!$L:$L,'Raw Data'!$B:$B,$B$2,'Raw Data'!$J:$J,H$2,'Raw Data'!$K:$K,"native",'Raw Data'!$H:$H,"51-60",'Raw Data'!$I:$I,"",'Raw Data'!$M:$M,"count") -> 186000 | I14: =SUMIFS('Raw Data'!$L:$L,'Raw Data'!$B:$B,$B$2,'Raw Data'!$J:$J,I$2,'Raw Data'!$K:$K,"native",'Raw Data'!$H:$H,"51-60",'Raw Data'!$I:$I,"",'Raw Data'!$M:$M,"count") -> 191000 | J14: =SUMIFS('Raw Data'!$L:$L,'Raw Data'!$B:$B,$B$2,'Raw Data'!$J:$J,J$2,'Raw Data'!$K:$K,"native",'Raw Data'!$H:$H,"51-60",'Raw Data'!$I:$I,"",'Raw Data'!$M:$M,"count") -> 195000 | ... Z14: =SUMIFS('Raw Data'!$L:$L,'Raw Data'!$B:$B,$B$2,'Raw Data'!$J:$J,Z$2,'Raw Data'!$K:$K,"native",'Raw Data'!$H:$H,"51-60",'Raw Data'!$I:$I,"",'Raw Data'!$M:$M,"count") -> 269000
A15: Users | B15: 61-70 | C15: =SUMIFS('Raw Data'!$L:$L,'Raw Data'!$B:$B,$B$2,'Raw Data'!$J:$J,C$2,'Raw Data'!$K:$K,"native",'Raw Data'!$H:$H,"61-70",'Raw Data'!$I:$I,"",'Raw Data'!$M:$M,"count") -> 71000 | D15: =SUMIFS('Raw Data'!$L:$L,'Raw Data'!$B:$B,$B$2,'Raw Data'!$J:$J,D$2,'Raw Data'!$K:$K,"native",'Raw Data'!$H:$H,"61-70",'Raw Data'!$I:$I,"",'Raw Data'!$M:$M,"count") -> 74000 | E15: =SUMIFS('Raw Data'!$L:$L,'Raw Data'!$B:$B,$B$2,'Raw Data'!$J:$J,E$2,'Raw Data'!$K:$K,"native",'Raw Data'!$H:$H,"61-70",'Raw Data'!$I:$I,"",'Raw Data'!$M:$M,"count") -> 76000 | F15: =SUMIFS('Raw Data'!$L:$L,'Raw Data'!$B:$B,$B$2,'Raw Data'!$J:$J,F$2,'Raw Data'!$K:$K,"native",'Raw Data'!$H:$H,"61-70",'Raw Data'!$I:$I,"",'Raw Data'!$M:$M,"count") -> 78000 | G15: =SUMIFS('Raw Data'!$L:$L,'Raw Data'!$B:$B,$B$2,'Raw Data'!$J:$J,G$2,'Raw Data'!$K:$K,"native",'Raw Data'!$H:$H,"61-70",'Raw Data'!$I:$I,"",'Raw Data'!$M:$M,"count") -> 81000 | H15: =SUMIFS('Raw Data'!$L:$L,'Raw Data'!$B:$B,$B$2,'Raw Data'!$J:$J,H$2,'Raw Data'!$K:$K,"native",'Raw Data'!$H:$H,"61-70",'Raw Data'!$I:$I,"",'Raw Data'!$M:$M,"count") -> 83000 | I15: =SUMIFS('Raw Data'!$L:$L,'Raw Data'!$B:$B,$B$2,'Raw Data'!$J:$J,I$2,'Raw Data'!$K:$K,"native",'Raw Data'!$H:$H,"61-70",'Raw Data'!$I:$I,"",'Raw Data'!$M:$M,"count") -> 86000 | J15: =SUMIFS('Raw Data'!$L:$L,'Raw Data'!$B:$B,$B$2,'Raw Data'!$J:$J,J$2,'Raw Data'!$K:$K,"native",'Raw Data'!$H:$H,"61-70",'Raw Data'!$I:$I,"",'Raw Data'!$M:$M,"count") -> 88000 | ... Z15: =SUMIFS('Raw Data'!$L:$L,'Raw Data'!$B:$B,$B$2,'Raw Data'!$J:$J,Z$2,'Raw Data'!$K:$K,"native",'Raw Data'!$H:$H,"61-70",'Raw Data'!$I:$I,"",'Raw Data'!$M:$M,"count") -> 129000
A16: Users | B16: 71-80 | C16: =SUMIFS('Raw Data'!$L:$L,'Raw Data'!$B:$B,$B$2,'Raw Data'!$J:$J,C$2,'Raw Data'!$K:$K,"native",'Raw Data'!$H:$H,"71-80",'Raw Data'!$I:$I,"",'Raw Data'!$M:$M,"count") -> 18000 | D16: =SUMIFS('Raw Data'!$L:$L,'Raw Data'!$B:$B,$B$2,'Raw Data'!$J:$J,D$2,'Raw Data'!$K:$K,"native",'Raw Data'!$H:$H,"71-80",'Raw Data'!$I:$I,"",'Raw Data'!$M:$M,"count") -> 19000 | E16: =SUMIFS('Raw Data'!$L:$L,'Raw Data'!$B:$B,$B$2,'Raw Data'!$J:$J,E$2,'Raw Data'!$K:$K,"native",'Raw Data'!$H:$H,"71-80",'Raw Data'!$I:$I,"",'Raw Data'!$M:$M,"count") -> 19000 | F16: =SUMIFS('Raw Data'!$L:$L,'Raw Data'!$B:$B,$B$2,'Raw Data'!$J:$J,F$2,'Raw Data'!$K:$K,"native",'Raw Data'!$H:$H,"71-80",'Raw Data'!$I:$I,"",'Raw Data'!$M:$M,"count") -> 20000 | G16: =SUMIFS('Raw Data'!$L:$L,'Raw Data'!$B:$B,$B$2,'Raw Data'!$J:$J,G$2,'Raw Data'!$K:$K,"native",'Raw Data'!$H:$H,"71-80",'Raw Data'!$I:$I,"",'Raw Data'!$M:$M,"count") -> 21000 | H16: =SUMIFS('Raw Data'!$L:$L,'Raw Data'!$B:$B,$B$2,'Raw Data'!$J:$J,H$2,'Raw Data'!$K:$K,"native",'Raw Data'!$H:$H,"71-80",'Raw Data'!$I:$I,"",'Raw Data'!$M:$M,"count") -> 21000 | I16: =SUMIFS('Raw Data'!$L:$L,'Raw Data'!$B:$B,$B$2,'Raw Data'!$J:$J,I$2,'Raw Data'!$K:$K,"native",'Raw Data'!$H:$H,"71-80",'Raw Data'!$I:$I,"",'Raw Data'!$M:$M,"count") -> 22000 | J16: =SUMIFS('Raw Data'!$L:$L,'Raw Data'!$B:$B,$B$2,'Raw Data'!$J:$J,J$2,'Raw Data'!$K:$K,"native",'Raw Data'!$H:$H,"71-80",'Raw Data'!$I:$I,"",'Raw Data'!$M:$M,"count") -> 23000 | ... Z16: =SUMIFS('Raw Data'!$L:$L,'Raw Data'!$B:$B,$B$2,'Raw Data'!$J:$J,Z$2,'Raw Data'!$K:$K,"native",'Raw Data'!$H:$H,"71-80",'Raw Data'!$I:$I,"",'Raw Data'!$M:$M,"count") -> 36000
A17: Users | B17: 81-90 | C17: =SUMIFS('Raw Data'!$L:$L,'Raw Data'!$B:$B,$B$2,'Raw Data'!$J:$J,C$2,'Raw Data'!$K:$K,"native",'Raw Data'!$H:$H,"81-90",'Raw Data'!$I:$I,"",'Raw Data'!$M:$M,"count") -> 4000 | D17: =SUMIFS('Raw Data'!$L:$L,'Raw Data'!$B:$B,$B$2,'Raw Data'!$J:$J,D$2,'Raw Data'!$K:$K,"native",'Raw Data'!$H:$H,"81-90",'Raw Data'!$I:$I,"",'Raw Data'!$M:$M,"count") -> 4000 | E17: =SUMIFS('Raw Data'!$L:$L,'Raw Data'!$B:$B,$B$2,'Raw Data'!$J:$J,E$2,'Raw Data'!$K:$K,"native",'Raw Data'!$H:$H,"81-90",'Raw Data'!$I:$I,"",'Raw Data'!$M:$M,"count") -> 4000 | F17: =SUMIFS('Raw Data'!$L:$L,'Raw Data'!$B:$B,$B$2,'Raw Data'!$J:$J,F$2,'Raw Data'!$K:$K,"native",'Raw Data'!$H:$H,"81-90",'Raw Data'!$I:$I,"",'Raw Data'!$M:$M,"count") -> 4000 | G17: =SUMIFS('Raw Data'!$L:$L,'Raw Data'!$B:$B,$B$2,'Raw Data'!$J:$J,G$2,'Raw Data'!$K:$K,"native",'Raw Data'!$H:$H,"81-90",'Raw Data'!$I:$I,"",'Raw Data'!$M:$M,"count") -> 4000 | H17: =SUMIFS('Raw Data'!$L:$L,'Raw Data'!$B:$B,$B$2,'Raw Data'!$J:$J,H$2,'Raw Data'!$K:$K,"native",'Raw Data'!$H:$H,"81-90",'Raw Data'!$I:$I,"",'Raw Data'!$M:$M,"count") -> 4000 | I17: =SUMIFS('Raw Data'!$L:$L,'Raw Data'!$B:$B,$B$2,'Raw Data'!$J:$J,I$2,'Raw Data'!$K:$K,"native",'Raw Data'!$H:$H,"81-90",'Raw Data'!$I:$I,"",'Raw Data'!$M:$M,"count") -> 4000 | J17: =SUMIFS('Raw Data'!$L:$L,'Raw Data'!$B:$B,$B$2,'Raw Data'!$J:$J,J$2,'Raw Data'!$K:$K,"native",'Raw Data'!$H:$H,"81-90",'Raw Data'!$I:$I,"",'Raw Data'!$M:$M,"count") -> 5000 | ... Z17: =SUMIFS('Raw Data'!$L:$L,'Raw Data'!$B:$B,$B$2,'Raw Data'!$J:$J,Z$2,'Raw Data'!$K:$K,"native",'Raw Data'!$H:$H,"81-90",'Raw Data'!$I:$I,"",'Raw Data'!$M:$M,"count") -> 9000
A18: Users | B18: <18 | C18: =SUMIFS('Raw Data'!$L:$L,'Raw Data'!$B:$B,$B$2,'Raw Data'!$J:$J,C$2,'Raw Data'!$K:$K,"native",'Raw Data'!$H:$H,"=<18",'Raw Data'!$I:$I,"",'Raw Data'!$M:$M,"count") -> 6000 | D18: =SUMIFS('Raw Data'!$L:$L,'Raw Data'!$B:$B,$B$2,'Raw Data'!$J:$J,D$2,'Raw Data'!$K:$K,"native",'Raw Data'!$H:$H,"=<18",'Raw Data'!$I:$I,"",'Raw Data'!$M:$M,"count") -> 6000 | E18: =SUMIFS('Raw Data'!$L:$L,'Raw Data'!$B:$B,$B$2,'Raw Data'!$J:$J,E$2,'Raw Data'!$K:$K,"native",'Raw Data'!$H:$H,"=<18",'Raw Data'!$I:$I,"",'Raw Data'!$M:$M,"count") -> 6000 | F18: =SUMIFS('Raw Data'!$L:$L,'Raw Data'!$B:$B,$B$2,'Raw Data'!$J:$J,F$2,'Raw Data'!$K:$K,"native",'Raw Data'!$H:$H,"=<18",'Raw Data'!$I:$I,"",'Raw Data'!$M:$M,"count") -> 6000 | G18: =SUMIFS('Raw Data'!$L:$L,'Raw Data'!$B:$B,$B$2,'Raw Data'!$J:$J,G$2,'Raw Data'!$K:$K,"native",'Raw Data'!$H:$H,"=<18",'Raw Data'!$I:$I,"",'Raw Data'!$M:$M,"count") -> 6000 | H18: =SUMIFS('Raw Data'!$L:$L,'Raw Data'!$B:$B,$B$2,'Raw Data'!$J:$J,H$2,'Raw Data'!$K:$K,"native",'Raw Data'!$H:$H,"=<18",'Raw Data'!$I:$I,"",'Raw Data'!$M:$M,"count") -> 7000 | I18: =SUMIFS('Raw Data'!$L:$L,'Raw Data'!$B:$B,$B$2,'Raw Data'!$J:$J,I$2,'Raw Data'!$K:$K,"native",'Raw Data'!$H:$H,"=<18",'Raw Data'!$I:$I,"",'Raw Data'!$M:$M,"count") -> 7000 | J18: =SUMIFS('Raw Data'!$L:$L,'Raw Data'!$B:$B,$B$2,'Raw Data'!$J:$J,J$2,'Raw Data'!$K:$K,"native",'Raw Data'!$H:$H,"=<18",'Raw Data'!$I:$I,"",'Raw Data'!$M:$M,"count") -> 8000 | ... Z18: =SUMIFS('Raw Data'!$L:$L,'Raw Data'!$B:$B,$B$2,'Raw Data'!$J:$J,Z$2,'Raw Data'!$K:$K,"native",'Raw Data'!$H:$H,"=<18",'Raw Data'!$I:$I,"",'Raw Data'!$M:$M,"count") -> 12000
A19: USERS BY USER TYPE (Number)
A20: Users | B20: Individual | C20: =SUMIFS('Raw Data'!$L:$L,'Raw Data'!$B:$B,$B$2,'Raw Data'!$J:$J,C$2,'Raw Data'!$K:$K,"native",'Raw Data'!$H:$H,"Individual",'Raw Data'!$I:$I,"",'Raw Data'!$M:$M,"count") -> 1530000 | D20: =SUMIFS('Raw Data'!$L:$L,'Raw Data'!$B:$B,$B$2,'Raw Data'!$J:$J,D$2,'Raw Data'!$K:$K,"native",'Raw Data'!$H:$H,"Individual",'Raw Data'!$I:$I,"",'Raw Data'!$M:$M,"count") -> 1570000 | E20: =SUMIFS('Raw Data'!$L:$L,'Raw Data'!$B:$B,$B$2,'Raw Data'!$J:$J,E$2,'Raw Data'!$K:$K,"native",'Raw Data'!$H:$H,"Individual",'Raw Data'!$I:$I,"",'Raw Data'!$M:$M,"count") -> 1600000 | F20: =SUMIFS('Raw Data'!$L:$L,'Raw Data'!$B:$B,$B$2,'Raw Data'!$J:$J,F$2,'Raw Data'!$K:$K,"native",'Raw Data'!$H:$H,"Individual",'Raw Data'!$I:$I,"",'Raw Data'!$M:$M,"count") -> 1640000 | G20: =SUMIFS('Raw Data'!$L:$L,'Raw Data'!$B:$B,$B$2,'Raw Data'!$J:$J,G$2,'Raw Data'!$K:$K,"native",'Raw Data'!$H:$H,"Individual",'Raw Data'!$I:$I,"",'Raw Data'!$M:$M,"count") -> 1680000 | H20: =SUMIFS('Raw Data'!$L:$L,'Raw Data'!$B:$B,$B$2,'Raw Data'!$J:$J,H$2,'Raw Data'!$K:$K,"native",'Raw Data'!$H:$H,"Individual",'Raw Data'!$I:$I,"",'Raw Data'!$M:$M,"count") -> 1710000 | I20: =SUMIFS('Raw Data'!$L:$L,'Raw Data'!$B:$B,$B$2,'Raw Data'!$J:$J,I$2,'Raw Data'!$K:$K,"native",'Raw Data'!$H:$H,"Individual",'Raw Data'!$I:$I,"",'Raw Data'!$M:$M,"count") -> 1740000 | J20: =SUMIFS('Raw Data'!$L:$L,'Raw Data'!$B:$B,$B$2,'Raw Data'!$J:$J,J$2,'Raw Data'!$K:$K,"native",'Raw Data'!$H:$H,"Individual",'Raw Data'!$I:$I,"",'Raw Data'!$M:$M,"count") -> 1780000 | ... Z20: =SUMIFS('Raw Data'!$L:$L,'Raw Data'!$B:$B,$B$2,'Raw Data'!$J:$J,Z$2,'Raw Data'!$K:$K,"native",'Raw Data'!$H:$H,"Individual",'Raw Data'!$I:$I,"",'Raw Data'!$M:$M,"count") -> 2330000
A21: Users | B21: Legal (entities) | C21: =SUMIFS('Raw Data'!$L:$L,'Raw Data'!$B:$B,$B$2,'Raw Data'!$J:$J,C$2,'Raw Data'!$K:$K,"native",'Raw Data'!$H:$H,"Legal (entities)",'Raw Data'!$I:$I,"",'Raw Data'!$M:$M,"count") -> 26500 | D21: =SUMIFS('Raw Data'!$L:$L,'Raw Data'!$B:$B,$B$2,'Raw Data'!$J:$J,D$2,'Raw Data'!$K:$K,"native",'Raw Data'!$H:$H,"Legal (entities)",'Raw Data'!$I:$I,"",'Raw Data'!$M:$M,"count") -> 28000 | E21: =SUMIFS('Raw Data'!$L:$L,'Raw Data'!$B:$B,$B$2,'Raw Data'!$J:$J,E$2,'Raw Data'!$K:$K,"native",'Raw Data'!$H:$H,"Legal (entities)",'Raw Data'!$I:$I,"",'Raw Data'!$M:$M,"count") -> 29000 | F21: =SUMIFS('Raw Data'!$L:$L,'Raw Data'!$B:$B,$B$2,'Raw Data'!$J:$J,F$2,'Raw Data'!$K:$K,"native",'Raw Data'!$H:$H,"Legal (entities)",'Raw Data'!$I:$I,"",'Raw Data'!$M:$M,"count") -> 30400 | G21: =SUMIFS('Raw Data'!$L:$L,'Raw Data'!$B:$B,$B$2,'Raw Data'!$J:$J,G$2,'Raw Data'!$K:$K,"native",'Raw Data'!$H:$H,"Legal (entities)",'Raw Data'!$I:$I,"",'Raw Data'!$M:$M,"count") -> 31600 | H21: =SUMIFS('Raw Data'!$L:$L,'Raw Data'!$B:$B,$B$2,'Raw Data'!$J:$J,H$2,'Raw Data'!$K:$K,"native",'Raw Data'!$H:$H,"Legal (entities)",'Raw Data'!$I:$I,"",'Raw Data'!$M:$M,"count") -> 32800 | I21: =SUMIFS('Raw Data'!$L:$L,'Raw Data'!$B:$B,$B$2,'Raw Data'!$J:$J,I$2,'Raw Data'!$K:$K,"native",'Raw Data'!$H:$H,"Legal (entities)",'Raw Data'!$I:$I,"",'Raw Data'!$M:$M,"count") -> 34000 | J21: =SUMIFS('Raw Data'!$L:$L,'Raw Data'!$B:$B,$B$2,'Raw Data'!$J:$J,J$2,'Raw Data'!$K:$K,"native",'Raw Data'!$H:$H,"Legal (entities)",'Raw Data'!$I:$I,"",'Raw Data'!$M:$M,"count") -> 35000 | ... Z21: =SUMIFS('Raw Data'!$L:$L,'Raw Data'!$B:$B,$B$2,'Raw Data'!$J:$J,Z$2,'Raw Data'!$K:$K,"native",'Raw Data'!$H:$H,"Legal (entities)",'Raw Data'!$I:$I,"",'Raw Data'!$M:$M,"count") -> 59000
A22: TRANSACTIONS BY TRANSACTION TYPE (Number)
A23: Transactions | B23: Money Transfers | C23: =SUMIFS('Raw Data'!$L:$L,'Raw Data'!$B:$B,$B$2,'Raw Data'!$J:$J,C$2,'Raw Data'!$K:$K,"native",'Raw Data'!$H:$H,"Money Transfers",'Raw Data'!$I:$I,"",'Raw Data'!$M:$M,"count") -> 6800000 | D23: =SUMIFS('Raw Data'!$L:$L,'Raw Data'!$B:$B,$B$2,'Raw Data'!$J:$J,D$2,'Raw Data'!$K:$K,"native",'Raw Data'!$H:$H,"Money Transfers",'Raw Data'!$I:$I,"",'Raw Data'!$M:$M,"count") -> 7620000 | E23: =SUMIFS('Raw Data'!$L:$L,'Raw Data'!$B:$B,$B$2,'Raw Data'!$J:$J,E$2,'Raw Data'!$K:$K,"native",'Raw Data'!$H:$H,"Money Transfers",'Raw Data'!$I:$I,"",'Raw Data'!$M:$M,"count") -> 7720000 | F23: =SUMIFS('Raw Data'!$L:$L,'Raw Data'!$B:$B,$B$2,'Raw Data'!$J:$J,F$2,'Raw Data'!$K:$K,"native",'Raw Data'!$H:$H,"Money Transfers",'Raw Data'!$I:$I,"",'Raw Data'!$M:$M,"count") -> 8570000 | G23: =SUMIFS('Raw Data'!$L:$L,'Raw Data'!$B:$B,$B$2,'Raw Data'!$J:$J,G$2,'Raw Data'!$K:$K,"native",'Raw Data'!$H:$H,"Money Transfers",'Raw Data'!$I:$I,"",'Raw Data'!$M:$M,"count") -> 8820000 | H23: =SUMIFS('Raw Data'!$L:$L,'Raw Data'!$B:$B,$B$2,'Raw Data'!$J:$J,H$2,'Raw Data'!$K:$K,"native",'Raw Data'!$H:$H,"Money Transfers",'Raw Data'!$I:$I,"",'Raw Data'!$M:$M,"count") -> 8450000 | I23: =SUMIFS('Raw Data'!$L:$L,'Raw Data'!$B:$B,$B$2,'Raw Data'!$J:$J,I$2,'Raw Data'!$K:$K,"native",'Raw Data'!$H:$H,"Money Transfers",'Raw Data'!$I:$I,"",'Raw Data'!$M:$M,"count") -> 10360000 | J23: =SUMIFS('Raw Data'!$L:$L,'Raw Data'!$B:$B,$B$2,'Raw Data'!$J:$J,J$2,'Raw Data'!$K:$K,"native",'Raw Data'!$H:$H,"Money Transfers",'Raw Data'!$I:$I,"",'Raw Data'!$M:$M,"count") -> 9780000 | ... Z23: =SUMIFS('Raw Data'!$L:$L,'Raw Data'!$B:$B,$B$2,'Raw Data'!$J:$J,Z$2,'Raw Data'!$K:$K,"native",'Raw Data'!$H:$H,"Money Transfers",'Raw Data'!$I:$I,"",'Raw Data'!$M:$M,"count") -> 19020000
A24: Transactions | B24: Purchases | C24: =SUMIFS('Raw Data'!$L:$L,'Raw Data'!$B:$B,$B$2,'Raw Data'!$J:$J,C$2,'Raw Data'!$K:$K,"native",'Raw Data'!$H:$H,"Purchases",'Raw Data'!$I:$I,"",'Raw Data'!$M:$M,"count") -> 1090000 | D24: =SUMIFS('Raw Data'!$L:$L,'Raw Data'!$B:$B,$B$2,'Raw Data'!$J:$J,D$2,'Raw Data'!$K:$K,"native",'Raw Data'!$H:$H,"Purchases",'Raw Data'!$I:$I,"",'Raw Data'!$M:$M,"count") -> 1240000 | E24: =SUMIFS('Raw Data'!$L:$L,'Raw Data'!$B:$B,$B$2,'Raw Data'!$J:$J,E$2,'Raw Data'!$K:$K,"native",'Raw Data'!$H:$H,"Purchases",'Raw Data'!$I:$I,"",'Raw Data'!$M:$M,"count") -> 1260000 | F24: =SUMIFS('Raw Data'!$L:$L,'Raw Data'!$B:$B,$B$2,'Raw Data'!$J:$J,F$2,'Raw Data'!$K:$K,"native",'Raw Data'!$H:$H,"Purchases",'Raw Data'!$I:$I,"",'Raw Data'!$M:$M,"count") -> 1430000 | G24: =SUMIFS('Raw Data'!$L:$L,'Raw Data'!$B:$B,$B$2,'Raw Data'!$J:$J,G$2,'Raw Data'!$K:$K,"native",'Raw Data'!$H:$H,"Purchases",'Raw Data'!$I:$I,"",'Raw Data'!$M:$M,"count") -> 1500000 | H24: =SUMIFS('Raw Data'!$L:$L,'Raw Data'!$B:$B,$B$2,'Raw Data'!$J:$J,H$2,'Raw Data'!$K:$K,"native",'Raw Data'!$H:$H,"Purchases",'Raw Data'!$I:$I,"",'Raw Data'!$M:$M,"count") -> 1450000 | I24: =SUMIFS('Raw Data'!$L:$L,'Raw Data'!$B:$B,$B$2,'Raw Data'!$J:$J,I$2,'Raw Data'!$K:$K,"native",'Raw Data'!$H:$H,"Purchases",'Raw Data'!$I:$I,"",'Raw Data'!$M:$M,"count") -> 1750000 | J24: =SUMIFS('Raw Data'!$L:$L,'Raw Data'!$B:$B,$B$2,'Raw Data'!$J:$J,J$2,'Raw Data'!$K:$K,"native",'Raw Data'!$H:$H,"Purchases",'Raw Data'!$I:$I,"",'Raw Data'!$M:$M,"count") -> 1740000 | ... Z24: =SUMIFS('Raw Data'!$L:$L,'Raw Data'!$B:$B,$B$2,'Raw Data'!$J:$J,Z$2,'Raw Data'!$K:$K,"native",'Raw Data'!$H:$H,"Purchases",'Raw Data'!$I:$I,"",'Raw Data'!$M:$M,"count") -> 4970000
A25: TRANSACTIONS BY TYPE — DETAIL (%)
A26: Transactions | B26: Money Transfers: Other | C26: =(SUMIFS('Raw Data'!$L:$L,'Raw Data'!$B:$B,$B$2,'Raw Data'!$J:$J,C$2,'Raw Data'!$K:$K,"native",'Raw Data'!$H:$H,"Money Transfers",'Raw Data'!$I:$I,"Other",'Raw Data'!$M:$M,"percent",'Raw Data'!$F:$F,"Number*"))/100 -> 0.034 | D26: =(SUMIFS('Raw Data'!$L:$L,'Raw Data'!$B:$B,$B$2,'Raw Data'!$J:$J,D$2,'Raw Data'!$K:$K,"native",'Raw Data'!$H:$H,"Money Transfers",'Raw Data'!$I:$I,"Other",'Raw Data'!$M:$M,"percent",'Raw Data'!$F:$F,"Number*"))/100 -> 0.037 | E26: =(SUMIFS('Raw Data'!$L:$L,'Raw Data'!$B:$B,$B$2,'Raw Data'!$J:$J,E$2,'Raw Data'!$K:$K,"native",'Raw Data'!$H:$H,"Money Transfers",'Raw Data'!$I:$I,"Other",'Raw Data'!$M:$M,"percent",'Raw Data'!$F:$F,"Number*"))/100 -> 0.036 | F26: =(SUMIFS('Raw Data'!$L:$L,'Raw Data'!$B:$B,$B$2,'Raw Data'!$J:$J,F$2,'Raw Data'!$K:$K,"native",'Raw Data'!$H:$H,"Money Transfers",'Raw Data'!$I:$I,"Other",'Raw Data'!$M:$M,"percent",'Raw Data'!$F:$F,"Number*"))/100 -> 0.0357 | G26: =(SUMIFS('Raw Data'!$L:$L,'Raw Data'!$B:$B,$B$2,'Raw Data'!$J:$J,G$2,'Raw Data'!$K:$K,"native",'Raw Data'!$H:$H,"Money Transfers",'Raw Data'!$I:$I,"Other",'Raw Data'!$M:$M,"percent",'Raw Data'!$F:$F,"Number*"))/100 -> 0.035 | H26: =(SUMIFS('Raw Data'!$L:$L,'Raw Data'!$B:$B,$B$2,'Raw Data'!$J:$J,H$2,'Raw Data'!$K:$K,"native",'Raw Data'!$H:$H,"Money Transfers",'Raw Data'!$I:$I,"Other",'Raw Data'!$M:$M,"percent",'Raw Data'!$F:$F,"Number*"))/100 -> 0.036 | I26: =(SUMIFS('Raw Data'!$L:$L,'Raw Data'!$B:$B,$B$2,'Raw Data'!$J:$J,I$2,'Raw Data'!$K:$K,"native",'Raw Data'!$H:$H,"Money Transfers",'Raw Data'!$I:$I,"Other",'Raw Data'!$M:$M,"percent",'Raw Data'!$F:$F,"Number*"))/100 -> 0.04 | J26: =(SUMIFS('Raw Data'!$L:$L,'Raw Data'!$B:$B,$B$2,'Raw Data'!$J:$J,J$2,'Raw Data'!$K:$K,"native",'Raw Data'!$H:$H,"Money Transfers",'Raw Data'!$I:$I,"Other",'Raw Data'!$M:$M,"percent",'Raw Data'!$F:$F,"Number*"))/100 -> 0.034 | ... M26: =(SUMIFS('Raw Data'!$L:$L,'Raw Data'!$B:$B,$B$2,'Raw Data'!$J:$J,M$2,'Raw Data'!$K:$K,"native",'Raw Data'!$H:$H,"Money Transfers",'Raw Data'!$I:$I,"Other",'Raw Data'!$M:$M,"percent",'Raw Data'!$F:$F,"Number*"))/100 -> 0.012 | T26: =(SUMIFS('Raw Data'!$L:$L,'Raw Data'!$B:$B,$B$2,'Raw Data'!$J:$J,T$2,'Raw Data'!$K:$K,"native",'Raw Data'!$H:$H,"Money Transfers",'Raw Data'!$I:$I,"Other",'Raw Data'!$M:$M,"percent",'Raw Data'!$F:$F,"Number*"))/100 -> 0 | Z26: =(SUMIFS('Raw Data'!$L:$L,'Raw Data'!$B:$B,$B$2,'Raw Data'!$J:$J,Z$2,'Raw Data'!$K:$K,"native",'Raw Data'!$H:$H,"Money Transfers",'Raw Data'!$I:$I,"Other",'Raw Data'!$M:$M,"percent",'Raw Data'!$F:$F,"Number*"))/100 -> 0.021
A27: Transactions | B27: Money Transfers: Transfer to Family/Friends | C27: =(SUMIFS('Raw Data'!$L:$L,'Raw Data'!$B:$B,$B$2,'Raw Data'!$J:$J,C$2,'Raw Data'!$K:$K,"native",'Raw Data'!$H:$H,"Money Transfers",'Raw Data'!$I:$I,"Transfer to Family/Friends",'Raw Data'!$M:$M,"percent",'Raw Data'!$F:$F,"Number*"))/100 -> 0.85 | D27: =(SUMIFS('Raw Data'!$L:$L,'Raw Data'!$B:$B,$B$2,'Raw Data'!$J:$J,D$2,'Raw Data'!$K:$K,"native",'Raw Data'!$H:$H,"Money Transfers",'Raw Data'!$I:$I,"Transfer to Family/Friends",'Raw Data'!$M:$M,"percent",'Raw Data'!$F:$F,"Number*"))/100 -> 0.849 | E27: =(SUMIFS('Raw Data'!$L:$L,'Raw Data'!$B:$B,$B$2,'Raw Data'!$J:$J,E$2,'Raw Data'!$K:$K,"native",'Raw Data'!$H:$H,"Money Transfers",'Raw Data'!$I:$I,"Transfer to Family/Friends",'Raw Data'!$M:$M,"percent",'Raw Data'!$F:$F,"Number*"))/100 -> 0.849 | F27: =(SUMIFS('Raw Data'!$L:$L,'Raw Data'!$B:$B,$B$2,'Raw Data'!$J:$J,F$2,'Raw Data'!$K:$K,"native",'Raw Data'!$H:$H,"Money Transfers",'Raw Data'!$I:$I,"Transfer to Family/Friends",'Raw Data'!$M:$M,"percent",'Raw Data'!$F:$F,"Number*"))/100 -> 0.8496 | G27: =(SUMIFS('Raw Data'!$L:$L,'Raw Data'!$B:$B,$B$2,'Raw Data'!$J:$J,G$2,'Raw Data'!$K:$K,"native",'Raw Data'!$H:$H,"Money Transfers",'Raw Data'!$I:$I,"Transfer to Family/Friends",'Raw Data'!$M:$M,"percent",'Raw Data'!$F:$F,"Number*"))/100 -> 0.852 | H27: =(SUMIFS('Raw Data'!$L:$L,'Raw Data'!$B:$B,$B$2,'Raw Data'!$J:$J,H$2,'Raw Data'!$K:$K,"native",'Raw Data'!$H:$H,"Money Transfers",'Raw Data'!$I:$I,"Transfer to Family/Friends",'Raw Data'!$M:$M,"percent",'Raw Data'!$F:$F,"Number*"))/100 -> 0.852 | I27: =(SUMIFS('Raw Data'!$L:$L,'Raw Data'!$B:$B,$B$2,'Raw Data'!$J:$J,I$2,'Raw Data'!$K:$K,"native",'Raw Data'!$H:$H,"Money Transfers",'Raw Data'!$I:$I,"Transfer to Family/Friends",'Raw Data'!$M:$M,"percent",'Raw Data'!$F:$F,"Number*"))/100 -> 0.85 | J27: =(SUMIFS('Raw Data'!$L:$L,'Raw Data'!$B:$B,$B$2,'Raw Data'!$J:$J,J$2,'Raw Data'!$K:$K,"native",'Raw Data'!$H:$H,"Money Transfers",'Raw Data'!$I:$I,"Transfer to Family/Friends",'Raw Data'!$M:$M,"percent",'Raw Data'!$F:$F,"Number*"))/100 -> 0.853 | ... M27: =(SUMIFS('Raw Data'!$L:$L,'Raw Data'!$B:$B,$B$2,'Raw Data'!$J:$J,M$2,'Raw Data'!$K:$K,"native",'Raw Data'!$H:$H,"Money Transfers",'Raw Data'!$I:$I,"Transfer to Family/Friends",'Raw Data'!$M:$M,"percent",'Raw Data'!$F:$F,"Number*"))/100 -> 0.884 | Z27: =(SUMIFS('Raw Data'!$L:$L,'Raw Data'!$B:$B,$B$2,'Raw Data'!$J:$J,Z$2,'Raw Data'!$K:$K,"native",'Raw Data'!$H:$H,"Money Transfers",'Raw Data'!$I:$I,"Transfer to Family/Friends",'Raw Data'!$M:$M,"percent",'Raw Data'!$F:$F,"Number*"))/100 -> 0.881
A28: Transactions | B28: Money Transfers: Transfer to Own Account | C28: =(SUMIFS('Raw Data'!$L:$L,'Raw Data'!$B:$B,$B$2,'Raw Data'!$J:$J,C$2,'Raw Data'!$K:$K,"native",'Raw Data'!$H:$H,"Money Transfers",'Raw Data'!$I:$I,"Transfer to Own Account",'Raw Data'!$M:$M,"percent",'Raw Data'!$F:$F,"Number*"))/100 -> 0.116 | D28: =(SUMIFS('Raw Data'!$L:$L,'Raw Data'!$B:$B,$B$2,'Raw Data'!$J:$J,D$2,'Raw Data'!$K:$K,"native",'Raw Data'!$H:$H,"Money Transfers",'Raw Data'!$I:$I,"Transfer to Own Account",'Raw Data'!$M:$M,"percent",'Raw Data'!$F:$F,"Number*"))/100 -> 0.114 | E28: =(SUMIFS('Raw Data'!$L:$L,'Raw Data'!$B:$B,$B$2,'Raw Data'!$J:$J,E$2,'Raw Data'!$K:$K,"native",'Raw Data'!$H:$H,"Money Transfers",'Raw Data'!$I:$I,"Transfer to Own Account",'Raw Data'!$M:$M,"percent",'Raw Data'!$F:$F,"Number*"))/100 -> 0.115 | F28: =(SUMIFS('Raw Data'!$L:$L,'Raw Data'!$B:$B,$B$2,'Raw Data'!$J:$J,F$2,'Raw Data'!$K:$K,"native",'Raw Data'!$H:$H,"Money Transfers",'Raw Data'!$I:$I,"Transfer to Own Account",'Raw Data'!$M:$M,"percent",'Raw Data'!$F:$F,"Number*"))/100 -> 0.1147 | G28: =(SUMIFS('Raw Data'!$L:$L,'Raw Data'!$B:$B,$B$2,'Raw Data'!$J:$J,G$2,'Raw Data'!$K:$K,"native",'Raw Data'!$H:$H,"Money Transfers",'Raw Data'!$I:$I,"Transfer to Own Account",'Raw Data'!$M:$M,"percent",'Raw Data'!$F:$F,"Number*"))/100 -> 0.113 | H28: =(SUMIFS('Raw Data'!$L:$L,'Raw Data'!$B:$B,$B$2,'Raw Data'!$J:$J,H$2,'Raw Data'!$K:$K,"native",'Raw Data'!$H:$H,"Money Transfers",'Raw Data'!$I:$I,"Transfer to Own Account",'Raw Data'!$M:$M,"percent",'Raw Data'!$F:$F,"Number*"))/100 -> 0.112 | I28: =(SUMIFS('Raw Data'!$L:$L,'Raw Data'!$B:$B,$B$2,'Raw Data'!$J:$J,I$2,'Raw Data'!$K:$K,"native",'Raw Data'!$H:$H,"Money Transfers",'Raw Data'!$I:$I,"Transfer to Own Account",'Raw Data'!$M:$M,"percent",'Raw Data'!$F:$F,"Number*"))/100 -> 0.11 | J28: =(SUMIFS('Raw Data'!$L:$L,'Raw Data'!$B:$B,$B$2,'Raw Data'!$J:$J,J$2,'Raw Data'!$K:$K,"native",'Raw Data'!$H:$H,"Money Transfers",'Raw Data'!$I:$I,"Transfer to Own Account",'Raw Data'!$M:$M,"percent",'Raw Data'!$F:$F,"Number*"))/100 -> 0.112 | ... M28: =(SUMIFS('Raw Data'!$L:$L,'Raw Data'!$B:$B,$B$2,'Raw Data'!$J:$J,M$2,'Raw Data'!$K:$K,"native",'Raw Data'!$H:$H,"Money Transfers",'Raw Data'!$I:$I,"Transfer to Own Account",'Raw Data'!$M:$M,"percent",'Raw Data'!$F:$F,"Number*"))/100 -> 0.104 | Z28: =(SUMIFS('Raw Data'!$L:$L,'Raw Data'!$B:$B,$B$2,'Raw Data'!$J:$J,Z$2,'Raw Data'!$K:$K,"native",'Raw Data'!$H:$H,"Money Transfers",'Raw Data'!$I:$I,"Transfer to Own Account",'Raw Data'!$M:$M,"percent",'Raw Data'!$F:$F,"Number*"))/100 -> 0.098
A29: Transactions | B29: Purchases: Non-QR Purchases | C29: =(SUMIFS('Raw Data'!$L:$L,'Raw Data'!$B:$B,$B$2,'Raw Data'!$J:$J,C$2,'Raw Data'!$K:$K,"native",'Raw Data'!$H:$H,"Purchases",'Raw Data'!$I:$I,"Non-QR Purchases",'Raw Data'!$M:$M,"percent",'Raw Data'!$F:$F,"Number*"))/100 -> 0.995 | D29: =(SUMIFS('Raw Data'!$L:$L,'Raw Data'!$B:$B,$B$2,'Raw Data'!$J:$J,D$2,'Raw Data'!$K:$K,"native",'Raw Data'!$H:$H,"Purchases",'Raw Data'!$I:$I,"Non-QR Purchases",'Raw Data'!$M:$M,"percent",'Raw Data'!$F:$F,"Number*"))/100 -> 0.995 | E29: =(SUMIFS('Raw Data'!$L:$L,'Raw Data'!$B:$B,$B$2,'Raw Data'!$J:$J,E$2,'Raw Data'!$K:$K,"native",'Raw Data'!$H:$H,"Purchases",'Raw Data'!$I:$I,"Non-QR Purchases",'Raw Data'!$M:$M,"percent",'Raw Data'!$F:$F,"Number*"))/100 -> 0.995 | F29: =(SUMIFS('Raw Data'!$L:$L,'Raw Data'!$B:$B,$B$2,'Raw Data'!$J:$J,F$2,'Raw Data'!$K:$K,"native",'Raw Data'!$H:$H,"Purchases",'Raw Data'!$I:$I,"Non-QR Purchases",'Raw Data'!$M:$M,"percent",'Raw Data'!$F:$F,"Number*"))/100 -> 0.995 | G29: =(SUMIFS('Raw Data'!$L:$L,'Raw Data'!$B:$B,$B$2,'Raw Data'!$J:$J,G$2,'Raw Data'!$K:$K,"native",'Raw Data'!$H:$H,"Purchases",'Raw Data'!$I:$I,"Non-QR Purchases",'Raw Data'!$M:$M,"percent",'Raw Data'!$F:$F,"Number*"))/100 -> 0.995 | H29: =(SUMIFS('Raw Data'!$L:$L,'Raw Data'!$B:$B,$B$2,'Raw Data'!$J:$J,H$2,'Raw Data'!$K:$K,"native",'Raw Data'!$H:$H,"Purchases",'Raw Data'!$I:$I,"Non-QR Purchases",'Raw Data'!$M:$M,"percent",'Raw Data'!$F:$F,"Number*"))/100 -> 0.994 | I29: =(SUMIFS('Raw Data'!$L:$L,'Raw Data'!$B:$B,$B$2,'Raw Data'!$J:$J,I$2,'Raw Data'!$K:$K,"native",'Raw Data'!$H:$H,"Purchases",'Raw Data'!$I:$I,"Non-QR Purchases",'Raw Data'!$M:$M,"percent",'Raw Data'!$F:$F,"Number*"))/100 -> 0.994 | J29: =(SUMIFS('Raw Data'!$L:$L,'Raw Data'!$B:$B,$B$2,'Raw Data'!$J:$J,J$2,'Raw Data'!$K:$K,"native",'Raw Data'!$H:$H,"Purchases",'Raw Data'!$I:$I,"Non-QR Purchases",'Raw Data'!$M:$M,"percent",'Raw Data'!$F:$F,"Number*"))/100 -> 0.993 | ... M29: =(SUMIFS('Raw Data'!$L:$L,'Raw Data'!$B:$B,$B$2,'Raw Data'!$J:$J,M$2,'Raw Data'!$K:$K,"native",'Raw Data'!$H:$H,"Purchases",'Raw Data'!$I:$I,"Non-QR Purchases",'Raw Data'!$M:$M,"percent",'Raw Data'!$F:$F,"Number*"))/100 -> 0.993 | Z29: =(SUMIFS('Raw Data'!$L:$L,'Raw Data'!$B:$B,$B$2,'Raw Data'!$J:$J,Z$2,'Raw Data'!$K:$K,"native",'Raw Data'!$H:$H,"Purchases",'Raw Data'!$I:$I,"Non-QR Purchases",'Raw Data'!$M:$M,"percent",'Raw Data'!$F:$F,"Number*"))/100 -> 0.992
A30: Transactions | B30: Purchases: QR Purchases | C30: =(SUMIFS('Raw Data'!$L:$L,'Raw Data'!$B:$B,$B$2,'Raw Data'!$J:$J,C$2,'Raw Data'!$K:$K,"native",'Raw Data'!$H:$H,"Purchases",'Raw Data'!$I:$I,"QR Purchases",'Raw Data'!$M:$M,"percent",'Raw Data'!$F:$F,"Number*"))/100 -> 0.005 | D30: =(SUMIFS('Raw Data'!$L:$L,'Raw Data'!$B:$B,$B$2,'Raw Data'!$J:$J,D$2,'Raw Data'!$K:$K,"native",'Raw Data'!$H:$H,"Purchases",'Raw Data'!$I:$I,"QR Purchases",'Raw Data'!$M:$M,"percent",'Raw Data'!$F:$F,"Number*"))/100 -> 0.005 | E30: =(SUMIFS('Raw Data'!$L:$L,'Raw Data'!$B:$B,$B$2,'Raw Data'!$J:$J,E$2,'Raw Data'!$K:$K,"native",'Raw Data'!$H:$H,"Purchases",'Raw Data'!$I:$I,"QR Purchases",'Raw Data'!$M:$M,"percent",'Raw Data'!$F:$F,"Number*"))/100 -> 0.005 | F30: =(SUMIFS('Raw Data'!$L:$L,'Raw Data'!$B:$B,$B$2,'Raw Data'!$J:$J,F$2,'Raw Data'!$K:$K,"native",'Raw Data'!$H:$H,"Purchases",'Raw Data'!$I:$I,"QR Purchases",'Raw Data'!$M:$M,"percent",'Raw Data'!$F:$F,"Number*"))/100 -> 0.005 | G30: =(SUMIFS('Raw Data'!$L:$L,'Raw Data'!$B:$B,$B$2,'Raw Data'!$J:$J,G$2,'Raw Data'!$K:$K,"native",'Raw Data'!$H:$H,"Purchases",'Raw Data'!$I:$I,"QR Purchases",'Raw Data'!$M:$M,"percent",'Raw Data'!$F:$F,"Number*"))/100 -> 0.005 | H30: =(SUMIFS('Raw Data'!$L:$L,'Raw Data'!$B:$B,$B$2,'Raw Data'!$J:$J,H$2,'Raw Data'!$K:$K,"native",'Raw Data'!$H:$H,"Purchases",'Raw Data'!$I:$I,"QR Purchases",'Raw Data'!$M:$M,"percent",'Raw Data'!$F:$F,"Number*"))/100 -> 0.006 | I30: =(SUMIFS('Raw Data'!$L:$L,'Raw Data'!$B:$B,$B$2,'Raw Data'!$J:$J,I$2,'Raw Data'!$K:$K,"native",'Raw Data'!$H:$H,"Purchases",'Raw Data'!$I:$I,"QR Purchases",'Raw Data'!$M:$M,"percent",'Raw Data'!$F:$F,"Number*"))/100 -> 0.006 | J30: =(SUMIFS('Raw Data'!$L:$L,'Raw Data'!$B:$B,$B$2,'Raw Data'!$J:$J,J$2,'Raw Data'!$K:$K,"native",'Raw Data'!$H:$H,"Purchases",'Raw Data'!$I:$I,"QR Purchases",'Raw Data'!$M:$M,"percent",'Raw Data'!$F:$F,"Number*"))/100 -> 0.007 | ... M30: =(SUMIFS('Raw Data'!$L:$L,'Raw Data'!$B:$B,$B$2,'Raw Data'!$J:$J,M$2,'Raw Data'!$K:$K,"native",'Raw Data'!$H:$H,"Purchases",'Raw Data'!$I:$I,"QR Purchases",'Raw Data'!$M:$M,"percent",'Raw Data'!$F:$F,"Number*"))/100 -> 0.007 | Z30: =(SUMIFS('Raw Data'!$L:$L,'Raw Data'!$B:$B,$B$2,'Raw Data'!$J:$J,Z$2,'Raw Data'!$K:$K,"native",'Raw Data'!$H:$H,"Purchases",'Raw Data'!$I:$I,"QR Purchases",'Raw Data'!$M:$M,"percent",'Raw Data'!$F:$F,"Number*"))/100 -> 0.008
A31: TRANSACTIONS BY TRANSACTION TYPE (Value, JOD)
A32: Transactions | B32: Money Transfers | C32: =SUMIFS('Raw Data'!$L:$L,'Raw Data'!$B:$B,$B$2,'Raw Data'!$J:$J,C$2,'Raw Data'!$K:$K,"native",'Raw Data'!$H:$H,"Money Transfers",'Raw Data'!$I:$I,"",'Raw Data'!$M:$M,"JOD") -> 936100000 | D32: =SUMIFS('Raw Data'!$L:$L,'Raw Data'!$B:$B,$B$2,'Raw Data'!$J:$J,D$2,'Raw Data'!$K:$K,"native",'Raw Data'!$H:$H,"Money Transfers",'Raw Data'!$I:$I,"",'Raw Data'!$M:$M,"JOD") -> 992600000 | E32: =SUMIFS('Raw Data'!$L:$L,'Raw Data'!$B:$B,$B$2,'Raw Data'!$J:$J,E$2,'Raw Data'!$K:$K,"native",'Raw Data'!$H:$H,"Money Transfers",'Raw Data'!$I:$I,"",'Raw Data'!$M:$M,"JOD") -> 954200000 | F32: =SUMIFS('Raw Data'!$L:$L,'Raw Data'!$B:$B,$B$2,'Raw Data'!$J:$J,F$2,'Raw Data'!$K:$K,"native",'Raw Data'!$H:$H,"Money Transfers",'Raw Data'!$I:$I,"",'Raw Data'!$M:$M,"JOD") -> 1080000000 | G32: =SUMIFS('Raw Data'!$L:$L,'Raw Data'!$B:$B,$B$2,'Raw Data'!$J:$J,G$2,'Raw Data'!$K:$K,"native",'Raw Data'!$H:$H,"Money Transfers",'Raw Data'!$I:$I,"",'Raw Data'!$M:$M,"JOD") -> 1080000000 | H32: =SUMIFS('Raw Data'!$L:$L,'Raw Data'!$B:$B,$B$2,'Raw Data'!$J:$J,H$2,'Raw Data'!$K:$K,"native",'Raw Data'!$H:$H,"Money Transfers",'Raw Data'!$I:$I,"",'Raw Data'!$M:$M,"JOD") -> 1030000000 | I32: =SUMIFS('Raw Data'!$L:$L,'Raw Data'!$B:$B,$B$2,'Raw Data'!$J:$J,I$2,'Raw Data'!$K:$K,"native",'Raw Data'!$H:$H,"Money Transfers",'Raw Data'!$I:$I,"",'Raw Data'!$M:$M,"JOD") -> 1260000000 | J32: =SUMIFS('Raw Data'!$L:$L,'Raw Data'!$B:$B,$B$2,'Raw Data'!$J:$J,J$2,'Raw Data'!$K:$K,"native",'Raw Data'!$H:$H,"Money Transfers",'Raw Data'!$I:$I,"",'Raw Data'!$M:$M,"JOD") -> 1170000000 | ... Z32: =SUMIFS('Raw Data'!$L:$L,'Raw Data'!$B:$B,$B$2,'Raw Data'!$J:$J,Z$2,'Raw Data'!$K:$K,"native",'Raw Data'!$H:$H,"Money Transfers",'Raw Data'!$I:$I,"",'Raw Data'!$M:$M,"JOD") -> 1730000000
A33: Transactions | B33: Purchases | C33: =SUMIFS('Raw Data'!$L:$L,'Raw Data'!$B:$B,$B$2,'Raw Data'!$J:$J,C$2,'Raw Data'!$K:$K,"native",'Raw Data'!$H:$H,"Purchases",'Raw Data'!$I:$I,"",'Raw Data'!$M:$M,"JOD") -> 208200000 | D33: =SUMIFS('Raw Data'!$L:$L,'Raw Data'!$B:$B,$B$2,'Raw Data'!$J:$J,D$2,'Raw Data'!$K:$K,"native",'Raw Data'!$H:$H,"Purchases",'Raw Data'!$I:$I,"",'Raw Data'!$M:$M,"JOD") -> 227200000 | E33: =SUMIFS('Raw Data'!$L:$L,'Raw Data'!$B:$B,$B$2,'Raw Data'!$J:$J,E$2,'Raw Data'!$K:$K,"native",'Raw Data'!$H:$H,"Purchases",'Raw Data'!$I:$I,"",'Raw Data'!$M:$M,"JOD") -> 220900000 | F33: =SUMIFS('Raw Data'!$L:$L,'Raw Data'!$B:$B,$B$2,'Raw Data'!$J:$J,F$2,'Raw Data'!$K:$K,"native",'Raw Data'!$H:$H,"Purchases",'Raw Data'!$I:$I,"",'Raw Data'!$M:$M,"JOD") -> 253700000 | G33: =SUMIFS('Raw Data'!$L:$L,'Raw Data'!$B:$B,$B$2,'Raw Data'!$J:$J,G$2,'Raw Data'!$K:$K,"native",'Raw Data'!$H:$H,"Purchases",'Raw Data'!$I:$I,"",'Raw Data'!$M:$M,"JOD") -> 259000000 | H33: =SUMIFS('Raw Data'!$L:$L,'Raw Data'!$B:$B,$B$2,'Raw Data'!$J:$J,H$2,'Raw Data'!$K:$K,"native",'Raw Data'!$H:$H,"Purchases",'Raw Data'!$I:$I,"",'Raw Data'!$M:$M,"JOD") -> 248700000 | I33: =SUMIFS('Raw Data'!$L:$L,'Raw Data'!$B:$B,$B$2,'Raw Data'!$J:$J,I$2,'Raw Data'!$K:$K,"native",'Raw Data'!$H:$H,"Purchases",'Raw Data'!$I:$I,"",'Raw Data'!$M:$M,"JOD") -> 300140000 | J33: =SUMIFS('Raw Data'!$L:$L,'Raw Data'!$B:$B,$B$2,'Raw Data'!$J:$J,J$2,'Raw Data'!$K:$K,"native",'Raw Data'!$H:$H,"Purchases",'Raw Data'!$I:$I,"",'Raw Data'!$M:$M,"JOD") -> 312800000 | ... Z33: =SUMIFS('Raw Data'!$L:$L,'Raw Data'!$B:$B,$B$2,'Raw Data'!$J:$J,Z$2,'Raw Data'!$K:$K,"native",'Raw Data'!$H:$H,"Purchases",'Raw Data'!$I:$I,"",'Raw Data'!$M:$M,"JOD") -> 694700000
A34: TRANSACTIONS BY TYPE — DETAIL (%)
A35: Transactions | B35: Money Transfers: Other | C35: =(SUMIFS('Raw Data'!$L:$L,'Raw Data'!$B:$B,$B$2,'Raw Data'!$J:$J,C$2,'Raw Data'!$K:$K,"native",'Raw Data'!$H:$H,"Money Transfers",'Raw Data'!$I:$I,"Other",'Raw Data'!$M:$M,"percent",'Raw Data'!$F:$F,"Value*"))/100 -> 0.053 | D35: =(SUMIFS('Raw Data'!$L:$L,'Raw Data'!$B:$B,$B$2,'Raw Data'!$J:$J,D$2,'Raw Data'!$K:$K,"native",'Raw Data'!$H:$H,"Money Transfers",'Raw Data'!$I:$I,"Other",'Raw Data'!$M:$M,"percent",'Raw Data'!$F:$F,"Value*"))/100 -> 0.056 | E35: =(SUMIFS('Raw Data'!$L:$L,'Raw Data'!$B:$B,$B$2,'Raw Data'!$J:$J,E$2,'Raw Data'!$K:$K,"native",'Raw Data'!$H:$H,"Money Transfers",'Raw Data'!$I:$I,"Other",'Raw Data'!$M:$M,"percent",'Raw Data'!$F:$F,"Value*"))/100 -> 0.0568 | F35: =(SUMIFS('Raw Data'!$L:$L,'Raw Data'!$B:$B,$B$2,'Raw Data'!$J:$J,F$2,'Raw Data'!$K:$K,"native",'Raw Data'!$H:$H,"Money Transfers",'Raw Data'!$I:$I,"Other",'Raw Data'!$M:$M,"percent",'Raw Data'!$F:$F,"Value*"))/100 -> 0.0572 | G35: =(SUMIFS('Raw Data'!$L:$L,'Raw Data'!$B:$B,$B$2,'Raw Data'!$J:$J,G$2,'Raw Data'!$K:$K,"native",'Raw Data'!$H:$H,"Money Transfers",'Raw Data'!$I:$I,"Other",'Raw Data'!$M:$M,"percent",'Raw Data'!$F:$F,"Value*"))/100 -> 0.057 | H35: =(SUMIFS('Raw Data'!$L:$L,'Raw Data'!$B:$B,$B$2,'Raw Data'!$J:$J,H$2,'Raw Data'!$K:$K,"native",'Raw Data'!$H:$H,"Money Transfers",'Raw Data'!$I:$I,"Other",'Raw Data'!$M:$M,"percent",'Raw Data'!$F:$F,"Value*"))/100 -> 0.058 | I35: =(SUMIFS('Raw Data'!$L:$L,'Raw Data'!$B:$B,$B$2,'Raw Data'!$J:$J,I$2,'Raw Data'!$K:$K,"native",'Raw Data'!$H:$H,"Money Transfers",'Raw Data'!$I:$I,"Other",'Raw Data'!$M:$M,"percent",'Raw Data'!$F:$F,"Value*"))/100 -> 0.06 | J35: =(SUMIFS('Raw Data'!$L:$L,'Raw Data'!$B:$B,$B$2,'Raw Data'!$J:$J,J$2,'Raw Data'!$K:$K,"native",'Raw Data'!$H:$H,"Money Transfers",'Raw Data'!$I:$I,"Other",'Raw Data'!$M:$M,"percent",'Raw Data'!$F:$F,"Value*"))/100 -> 0.055 | ... M35: =(SUMIFS('Raw Data'!$L:$L,'Raw Data'!$B:$B,$B$2,'Raw Data'!$J:$J,M$2,'Raw Data'!$K:$K,"native",'Raw Data'!$H:$H,"Money Transfers",'Raw Data'!$I:$I,"Other",'Raw Data'!$M:$M,"percent",'Raw Data'!$F:$F,"Value*"))/100 -> 0.03 | Z35: =(SUMIFS('Raw Data'!$L:$L,'Raw Data'!$B:$B,$B$2,'Raw Data'!$J:$J,Z$2,'Raw Data'!$K:$K,"native",'Raw Data'!$H:$H,"Money Transfers",'Raw Data'!$I:$I,"Other",'Raw Data'!$M:$M,"percent",'Raw Data'!$F:$F,"Value*"))/100 -> 0.059
A36: Transactions | B36: Money Transfers: Transfer to Family/Friends | C36: =(SUMIFS('Raw Data'!$L:$L,'Raw Data'!$B:$B,$B$2,'Raw Data'!$J:$J,C$2,'Raw Data'!$K:$K,"native",'Raw Data'!$H:$H,"Money Transfers",'Raw Data'!$I:$I,"Transfer to Family/Friends",'Raw Data'!$M:$M,"percent",'Raw Data'!$F:$F,"Value*"))/100 -> 0.738 | D36: =(SUMIFS('Raw Data'!$L:$L,'Raw Data'!$B:$B,$B$2,'Raw Data'!$J:$J,D$2,'Raw Data'!$K:$K,"native",'Raw Data'!$H:$H,"Money Transfers",'Raw Data'!$I:$I,"Transfer to Family/Friends",'Raw Data'!$M:$M,"percent",'Raw Data'!$F:$F,"Value*"))/100 -> 0.731 | E36: =(SUMIFS('Raw Data'!$L:$L,'Raw Data'!$B:$B,$B$2,'Raw Data'!$J:$J,E$2,'Raw Data'!$K:$K,"native",'Raw Data'!$H:$H,"Money Transfers",'Raw Data'!$I:$I,"Transfer to Family/Friends",'Raw Data'!$M:$M,"percent",'Raw Data'!$F:$F,"Value*"))/100 -> 0.7286 | F36: =(SUMIFS('Raw Data'!$L:$L,'Raw Data'!$B:$B,$B$2,'Raw Data'!$J:$J,F$2,'Raw Data'!$K:$K,"native",'Raw Data'!$H:$H,"Money Transfers",'Raw Data'!$I:$I,"Transfer to Family/Friends",'Raw Data'!$M:$M,"percent",'Raw Data'!$F:$F,"Value*"))/100 -> 0.7215 | G36: =(SUMIFS('Raw Data'!$L:$L,'Raw Data'!$B:$B,$B$2,'Raw Data'!$J:$J,G$2,'Raw Data'!$K:$K,"native",'Raw Data'!$H:$H,"Money Transfers",'Raw Data'!$I:$I,"Transfer to Family/Friends",'Raw Data'!$M:$M,"percent",'Raw Data'!$F:$F,"Value*"))/100 -> 0.722 | H36: =(SUMIFS('Raw Data'!$L:$L,'Raw Data'!$B:$B,$B$2,'Raw Data'!$J:$J,H$2,'Raw Data'!$K:$K,"native",'Raw Data'!$H:$H,"Money Transfers",'Raw Data'!$I:$I,"Transfer to Family/Friends",'Raw Data'!$M:$M,"percent",'Raw Data'!$F:$F,"Value*"))/100 -> 0.724 | I36: =(SUMIFS('Raw Data'!$L:$L,'Raw Data'!$B:$B,$B$2,'Raw Data'!$J:$J,I$2,'Raw Data'!$K:$K,"native",'Raw Data'!$H:$H,"Money Transfers",'Raw Data'!$I:$I,"Transfer to Family/Friends",'Raw Data'!$M:$M,"percent",'Raw Data'!$F:$F,"Value*"))/100 -> 0.728 | J36: =(SUMIFS('Raw Data'!$L:$L,'Raw Data'!$B:$B,$B$2,'Raw Data'!$J:$J,J$2,'Raw Data'!$K:$K,"native",'Raw Data'!$H:$H,"Money Transfers",'Raw Data'!$I:$I,"Transfer to Family/Friends",'Raw Data'!$M:$M,"percent",'Raw Data'!$F:$F,"Value*"))/100 -> 0.716 | ... M36: =(SUMIFS('Raw Data'!$L:$L,'Raw Data'!$B:$B,$B$2,'Raw Data'!$J:$J,M$2,'Raw Data'!$K:$K,"native",'Raw Data'!$H:$H,"Money Transfers",'Raw Data'!$I:$I,"Transfer to Family/Friends",'Raw Data'!$M:$M,"percent",'Raw Data'!$F:$F,"Value*"))/100 -> 0.753 | Z36: =(SUMIFS('Raw Data'!$L:$L,'Raw Data'!$B:$B,$B$2,'Raw Data'!$J:$J,Z$2,'Raw Data'!$K:$K,"native",'Raw Data'!$H:$H,"Money Transfers",'Raw Data'!$I:$I,"Transfer to Family/Friends",'Raw Data'!$M:$M,"percent",'Raw Data'!$F:$F,"Value*"))/100 -> 0.718
A37: Transactions | B37: Money Transfers: Transfer to Own Account | C37: =(SUMIFS('Raw Data'!$L:$L,'Raw Data'!$B:$B,$B$2,'Raw Data'!$J:$J,C$2,'Raw Data'!$K:$K,"native",'Raw Data'!$H:$H,"Money Transfers",'Raw Data'!$I:$I,"Transfer to Own Account",'Raw Data'!$M:$M,"percent",'Raw Data'!$F:$F,"Value*"))/100 -> 0.209 | D37: =(SUMIFS('Raw Data'!$L:$L,'Raw Data'!$B:$B,$B$2,'Raw Data'!$J:$J,D$2,'Raw Data'!$K:$K,"native",'Raw Data'!$H:$H,"Money Transfers",'Raw Data'!$I:$I,"Transfer to Own Account",'Raw Data'!$M:$M,"percent",'Raw Data'!$F:$F,"Value*"))/100 -> 0.213 | E37: =(SUMIFS('Raw Data'!$L:$L,'Raw Data'!$B:$B,$B$2,'Raw Data'!$J:$J,E$2,'Raw Data'!$K:$K,"native",'Raw Data'!$H:$H,"Money Transfers",'Raw Data'!$I:$I,"Transfer to Own Account",'Raw Data'!$M:$M,"percent",'Raw Data'!$F:$F,"Value*"))/100 -> 0.2146 | F37: =(SUMIFS('Raw Data'!$L:$L,'Raw Data'!$B:$B,$B$2,'Raw Data'!$J:$J,F$2,'Raw Data'!$K:$K,"native",'Raw Data'!$H:$H,"Money Transfers",'Raw Data'!$I:$I,"Transfer to Own Account",'Raw Data'!$M:$M,"percent",'Raw Data'!$F:$F,"Value*"))/100 -> 0.2213 | G37: =(SUMIFS('Raw Data'!$L:$L,'Raw Data'!$B:$B,$B$2,'Raw Data'!$J:$J,G$2,'Raw Data'!$K:$K,"native",'Raw Data'!$H:$H,"Money Transfers",'Raw Data'!$I:$I,"Transfer to Own Account",'Raw Data'!$M:$M,"percent",'Raw Data'!$F:$F,"Value*"))/100 -> 0.221 | H37: =(SUMIFS('Raw Data'!$L:$L,'Raw Data'!$B:$B,$B$2,'Raw Data'!$J:$J,H$2,'Raw Data'!$K:$K,"native",'Raw Data'!$H:$H,"Money Transfers",'Raw Data'!$I:$I,"Transfer to Own Account",'Raw Data'!$M:$M,"percent",'Raw Data'!$F:$F,"Value*"))/100 -> 0.218 | I37: =(SUMIFS('Raw Data'!$L:$L,'Raw Data'!$B:$B,$B$2,'Raw Data'!$J:$J,I$2,'Raw Data'!$K:$K,"native",'Raw Data'!$H:$H,"Money Transfers",'Raw Data'!$I:$I,"Transfer to Own Account",'Raw Data'!$M:$M,"percent",'Raw Data'!$F:$F,"Value*"))/100 -> 0.212 | J37: =(SUMIFS('Raw Data'!$L:$L,'Raw Data'!$B:$B,$B$2,'Raw Data'!$J:$J,J$2,'Raw Data'!$K:$K,"native",'Raw Data'!$H:$H,"Money Transfers",'Raw Data'!$I:$I,"Transfer to Own Account",'Raw Data'!$M:$M,"percent",'Raw Data'!$F:$F,"Value*"))/100 -> 0.229 | ... M37: =(SUMIFS('Raw Data'!$L:$L,'Raw Data'!$B:$B,$B$2,'Raw Data'!$J:$J,M$2,'Raw Data'!$K:$K,"native",'Raw Data'!$H:$H,"Money Transfers",'Raw Data'!$I:$I,"Transfer to Own Account",'Raw Data'!$M:$M,"percent",'Raw Data'!$F:$F,"Value*"))/100 -> 0.217 | Z37: =(SUMIFS('Raw Data'!$L:$L,'Raw Data'!$B:$B,$B$2,'Raw Data'!$J:$J,Z$2,'Raw Data'!$K:$K,"native",'Raw Data'!$H:$H,"Money Transfers",'Raw Data'!$I:$I,"Transfer to Own Account",'Raw Data'!$M:$M,"percent",'Raw Data'!$F:$F,"Value*"))/100 -> 0.223
A38: Transactions | B38: Purchases: Non-QR Purchases | C38: =(SUMIFS('Raw Data'!$L:$L,'Raw Data'!$B:$B,$B$2,'Raw Data'!$J:$J,C$2,'Raw Data'!$K:$K,"native",'Raw Data'!$H:$H,"Purchases",'Raw Data'!$I:$I,"Non-QR Purchases",'Raw Data'!$M:$M,"percent",'Raw Data'!$F:$F,"Value*"))/100 -> 0.9992 | D38: =(SUMIFS('Raw Data'!$L:$L,'Raw Data'!$B:$B,$B$2,'Raw Data'!$J:$J,D$2,'Raw Data'!$K:$K,"native",'Raw Data'!$H:$H,"Purchases",'Raw Data'!$I:$I,"Non-QR Purchases",'Raw Data'!$M:$M,"percent",'Raw Data'!$F:$F,"Value*"))/100 -> 0.9994 | E38: =(SUMIFS('Raw Data'!$L:$L,'Raw Data'!$B:$B,$B$2,'Raw Data'!$J:$J,E$2,'Raw Data'!$K:$K,"native",'Raw Data'!$H:$H,"Purchases",'Raw Data'!$I:$I,"Non-QR Purchases",'Raw Data'!$M:$M,"percent",'Raw Data'!$F:$F,"Value*"))/100 -> 0.9992 | F38: =(SUMIFS('Raw Data'!$L:$L,'Raw Data'!$B:$B,$B$2,'Raw Data'!$J:$J,F$2,'Raw Data'!$K:$K,"native",'Raw Data'!$H:$H,"Purchases",'Raw Data'!$I:$I,"Non-QR Purchases",'Raw Data'!$M:$M,"percent",'Raw Data'!$F:$F,"Value*"))/100 -> 0.9993 | G38: =(SUMIFS('Raw Data'!$L:$L,'Raw Data'!$B:$B,$B$2,'Raw Data'!$J:$J,G$2,'Raw Data'!$K:$K,"native",'Raw Data'!$H:$H,"Purchases",'Raw Data'!$I:$I,"Non-QR Purchases",'Raw Data'!$M:$M,"percent",'Raw Data'!$F:$F,"Value*"))/100 -> 0.9993 | H38: =(SUMIFS('Raw Data'!$L:$L,'Raw Data'!$B:$B,$B$2,'Raw Data'!$J:$J,H$2,'Raw Data'!$K:$K,"native",'Raw Data'!$H:$H,"Purchases",'Raw Data'!$I:$I,"Non-QR Purchases",'Raw Data'!$M:$M,"percent",'Raw Data'!$F:$F,"Value*"))/100 -> 0.9992 | I38: =(SUMIFS('Raw Data'!$L:$L,'Raw Data'!$B:$B,$B$2,'Raw Data'!$J:$J,I$2,'Raw Data'!$K:$K,"native",'Raw Data'!$H:$H,"Purchases",'Raw Data'!$I:$I,"Non-QR Purchases",'Raw Data'!$M:$M,"percent",'Raw Data'!$F:$F,"Value*"))/100 -> 0.9993 | J38: =(SUMIFS('Raw Data'!$L:$L,'Raw Data'!$B:$B,$B$2,'Raw Data'!$J:$J,J$2,'Raw Data'!$K:$K,"native",'Raw Data'!$H:$H,"Purchases",'Raw Data'!$I:$I,"Non-QR Purchases",'Raw Data'!$M:$M,"percent",'Raw Data'!$F:$F,"Value*"))/100 -> 0.9992 | ... M38: =(SUMIFS('Raw Data'!$L:$L,'Raw Data'!$B:$B,$B$2,'Raw Data'!$J:$J,M$2,'Raw Data'!$K:$K,"native",'Raw Data'!$H:$H,"Purchases",'Raw Data'!$I:$I,"Non-QR Purchases",'Raw Data'!$M:$M,"percent",'Raw Data'!$F:$F,"Value*"))/100 -> 0.9992 | Z38: =(SUMIFS('Raw Data'!$L:$L,'Raw Data'!$B:$B,$B$2,'Raw Data'!$J:$J,Z$2,'Raw Data'!$K:$K,"native",'Raw Data'!$H:$H,"Purchases",'Raw Data'!$I:$I,"Non-QR Purchases",'Raw Data'!$M:$M,"percent",'Raw Data'!$F:$F,"Value*"))/100 -> 0.9991
A39: Transactions | B39: Purchases: QR Purchases | C39: =(SUMIFS('Raw Data'!$L:$L,'Raw Data'!$B:$B,$B$2,'Raw Data'!$J:$J,C$2,'Raw Data'!$K:$K,"native",'Raw Data'!$H:$H,"Purchases",'Raw Data'!$I:$I,"QR Purchases",'Raw Data'!$M:$M,"percent",'Raw Data'!$F:$F,"Value*"))/100 -> 0.0008 | D39: =(SUMIFS('Raw Data'!$L:$L,'Raw Data'!$B:$B,$B$2,'Raw Data'!$J:$J,D$2,'Raw Data'!$K:$K,"native",'Raw Data'!$H:$H,"Purchases",'Raw Data'!$I:$I,"QR Purchases",'Raw Data'!$M:$M,"percent",'Raw Data'!$F:$F,"Value*"))/100 -> 0.0006 | E39: =(SUMIFS('Raw Data'!$L:$L,'Raw Data'!$B:$B,$B$2,'Raw Data'!$J:$J,E$2,'Raw Data'!$K:$K,"native",'Raw Data'!$H:$H,"Purchases",'Raw Data'!$I:$I,"QR Purchases",'Raw Data'!$M:$M,"percent",'Raw Data'!$F:$F,"Value*"))/100 -> 0.0008 | F39: =(SUMIFS('Raw Data'!$L:$L,'Raw Data'!$B:$B,$B$2,'Raw Data'!$J:$J,F$2,'Raw Data'!$K:$K,"native",'Raw Data'!$H:$H,"Purchases",'Raw Data'!$I:$I,"QR Purchases",'Raw Data'!$M:$M,"percent",'Raw Data'!$F:$F,"Value*"))/100 -> 0.0007 | G39: =(SUMIFS('Raw Data'!$L:$L,'Raw Data'!$B:$B,$B$2,'Raw Data'!$J:$J,G$2,'Raw Data'!$K:$K,"native",'Raw Data'!$H:$H,"Purchases",'Raw Data'!$I:$I,"QR Purchases",'Raw Data'!$M:$M,"percent",'Raw Data'!$F:$F,"Value*"))/100 -> 0.0007 | H39: =(SUMIFS('Raw Data'!$L:$L,'Raw Data'!$B:$B,$B$2,'Raw Data'!$J:$J,H$2,'Raw Data'!$K:$K,"native",'Raw Data'!$H:$H,"Purchases",'Raw Data'!$I:$I,"QR Purchases",'Raw Data'!$M:$M,"percent",'Raw Data'!$F:$F,"Value*"))/100 -> 0.0008 | I39: =(SUMIFS('Raw Data'!$L:$L,'Raw Data'!$B:$B,$B$2,'Raw Data'!$J:$J,I$2,'Raw Data'!$K:$K,"native",'Raw Data'!$H:$H,"Purchases",'Raw Data'!$I:$I,"QR Purchases",'Raw Data'!$M:$M,"percent",'Raw Data'!$F:$F,"Value*"))/100 -> 0.0007 | J39: =(SUMIFS('Raw Data'!$L:$L,'Raw Data'!$B:$B,$B$2,'Raw Data'!$J:$J,J$2,'Raw Data'!$K:$K,"native",'Raw Data'!$H:$H,"Purchases",'Raw Data'!$I:$I,"QR Purchases",'Raw Data'!$M:$M,"percent",'Raw Data'!$F:$F,"Value*"))/100 -> 0.0008 | ... M39: =(SUMIFS('Raw Data'!$L:$L,'Raw Data'!$B:$B,$B$2,'Raw Data'!$J:$J,M$2,'Raw Data'!$K:$K,"native",'Raw Data'!$H:$H,"Purchases",'Raw Data'!$I:$I,"QR Purchases",'Raw Data'!$M:$M,"percent",'Raw Data'!$F:$F,"Value*"))/100 -> 0.0008 | Z39: =(SUMIFS('Raw Data'!$L:$L,'Raw Data'!$B:$B,$B$2,'Raw Data'!$J:$J,Z$2,'Raw Data'!$K:$K,"native",'Raw Data'!$H:$H,"Purchases",'Raw Data'!$I:$I,"QR Purchases",'Raw Data'!$M:$M,"percent",'Raw Data'!$F:$F,"Value*"))/100 -> 0.0009
A40: Transactions | B40: Purchases: Non-QR
...

Sheet JoMoPay
A1: JoMoPay (Mobile Wallets)
