Workbook
Name Slicer_dimension_L1: #N/A
Name Slicer_metric: #N/A
Name Slicer_system: #N/A

Sheet README
A1: JOPACC Payment Systems Quarterly Report - Consolidated Dataset
A3: Source: Jordan Payments & Clearing Company (JOPACC) "Payment Systems Quarterly Report" PDFs for Q3 2024, Q4 2024, Q1 2025, Q2 2025, Q3 2025, Q4 2025, Q1 2026 and Q2 2026.
A5: Sheets in this workbook:
A6: • CliQ - instant/person-to-person payments (users + transactions)
A7: • JoMoPay - mobile wallet payments (users + transactions)
A8: • eFAWATEERcom - bill payment platform (users + transactions + billers)
A9: • ACH - Automated Clearing House (JOD + foreign-currency transactions)
A10: • ECCU - Electronic Cheque Clearing Unit (cheques + returned cheques)
A11: • CliQ_JoMoPay_Interop - cross-system money-transfer interoperability
A13: Layout:
A14: Each sheet lists one metric per row (grouped under shaded section headers) with the eight quarters running left-to-right in columns C:J. Counts and JOD values are stored as raw numbers (not text with "M"/"B" suffixes) so they can be charted, filtered, or fed into further formulas directly.
A15: Percentage rows are stored as true Excel percentages (e.g. 96.3%), and light-grey "Check" rows use live formulas (e.g. Money Transfer + Purchases) to verify that the component figures reconcile with the reported totals.
... A26: • A few cells now differ slightly from the original static workbook: those were manual transcription slips in the old file, corrected automatically now that formulas read straight from Data.

Sheet Data
A1: report_period | B1: system | C1: page | D1: content_type | E1: extracted_from | F1: metric | G1: system_title | H1: dimension_L1 | I1: dimension_L2 | J1: event_period | K1: period_scope | L1: value | M1: unit | N1: raw_text | O1: chart_labeled | P1: reading_rank | Q1: note
A2: 2024-Q3 | B2: cliq | C2: 2 | D2: category | E2: category_chart | F2: Number of Users | G2: Users | H2: 18-30 | J2: 2024-Q3 | K2: native | L2: 591000 | M2: count | N2: 591.0 K
A3: 2024-Q3 | B3: cliq | C3: 2 | D3: category | E3: category_chart | F3: Number of Users | G3: Users | H3: 31-40 | J3: 2024-Q3 | K3: native | L3: 409200 | M3: count | N3: 409.2 K
A4: 2024-Q3 | B4: cliq | C4: 2 | D4: category | E4: category_chart | F4: Number of Users | G4: Users | H4: 41-50 | J4: 2024-Q3 | K4: native | L4: 267100 | M4: count | N4: 267.1 K
A5: 2024-Q3 | B5: cliq | C5: 2 | D5: category | E5: category_chart | F5: Number of Users | G5: Users | H5: 51-60 | J5: 2024-Q3 | K5: native | L5: 162500 | M5: count | N5: 162.5 K
A6: 2024-Q3 | B6: cliq | C6: 2 | D6: category | E6: category_chart | F6: Number of Users | G6: Users | H6: 61-70 | J6: 2024-Q3 | K6: native | L6: 71100 | M6: count | N6: 71.1 K
A7: 2024-Q3 | B7: cliq | C7: 2 | D7: category | E7: category_chart | F7: Number of Users | G7: Users | H7: 71-80 | J7: 2024-Q3 | K7: native | L7: 18100 | M7: count | N7: 18.1 K
A8: 2024-Q3 | B8: cliq | C8: 2 | D8: category | E8: category_chart | F8: Number of Users | G8: Users | H8: 81-90 | J8: 2024-Q3 | K8: native | L8: 3700 | M8: count | N8: 3.7 K
A9: 2024-Q3 | B9: cliq | C9: 2 | D9: category | E9: category_chart | F9: Number of Users | G9: Users | H9: <18 | J9: 2024-Q3 | K9: native | L9: 5800 | M9: count | N9: 5.8 K
A10: 2024-Q3 | B10: cliq | C10: 2 | D10: category | E10: category_chart | F10: Number of Users | G10: Users | H10: Female | J10: 2024-Q3 | K10: native | L10: 541300 | M10: count | N10: 541.3 K
A11: 2024-Q3 | B11: cliq | C11: 2 | D11: category | E11: category_chart | F11: Number of Users | G11: Users | H11: Individual | J11: 2024-Q3 | K11: native | L11: 1530000 | M11: count | N11: 1.53 M
A12: 2024-Q3 | B12: cliq | C12: 2 | D12: category | E12: category_chart | F12: Number of Users | G12: Users | H12: Jordanian | J12: 2024-Q3 | K12: native | L12: 1500000 | M12: count | N12: 1.50 M
A13: 2024-Q3 | B13: cliq | C13: 2 | D13: category | E13: category_chart | F13: Number of Users | G13: Users | H13: Legal (entities) | J13: 2024-Q3 | K13: native | L13: 26500 | M13: count | N13: 26.5 K
... A15: 2024-Q3 | B15: cliq | C15: 2 | D15: category | E15: category_chart | F15: Number of Users | G15: Users | H15: Non-Jordanian | J15: 2024-Q3 | K15: native | L15: 55000 | M15: count | N15: 55.0 K
A16: 2024-Q3 | B16: cliq | C16: 2 | D16: chart_point | E16: trend_chart | F16: Number of Users | G16: Users | J16: 2024-Q1 | K16: trailing_chart_point | L16: 1330000 | M16: count | N16: 1.33 M | O16: TRUE | P16: newest | Q16: no native/stat_box reading of 2024-Q1 exists anywhere in this corpus (its own quarterly PDF wasn't part of this extraction) - marked newest as the earliest available trailing_chart_point reading of it, per §8 rule 4's fallback
A17: 2024-Q3 | B17: cliq | C17: 2 | D17: chart_point | E17: trend_chart | F17: Number of Users | G17: Users | J17: 2024-Q2 | K17: trailing_chart_point | L17: 1430000 | M17: count | N17: 1.43 M | O17: TRUE | P17: newest | Q17: no native/stat_box reading of 2024-Q2 exists anywhere in this corpus (its own quarterly PDF wasn't part of this extraction) - marked newest as the earliest available trailing_chart_point reading of it, per §8 rule 4's fallback
A18: 2024-Q3 | B18: cliq | C18: 2 | D18: kpi | E18: stat_box | F18: Number of Users | G18: Users | J18: 2024-Q3 | K18: native | L18: 1560000 | M18: count | N18: 1.56 M
A19: 2024-Q4 | B19: cliq | C19: 2 | D19: category | E19: category_chart | F19: Number of Users | G19: Users | H19: 18-30 | J19: 2024-Q4 | K19: native | L19: 626000 | M19: count | N19: 626.0 K
A20: 2024-Q4 | B20: cliq | C20: 2 | D20: category | E20: category_chart | F20: Number of Users | G20: Users | H20: 31-40 | J20: 2024-Q4 | K20: native | L20: 437900 | M20: count | N20: 437.9 K
A21: 2024-Q4 | B21: cliq | C21: 2 | D21: category | E21: category_chart | F21: Number of Users | G21: Users | H21: 41-50 | J21: 2024-Q4 | K21: native | L21: 289300 | M21: count | N21: 289.3 K
A22: 2024-Q4 | B22: cliq | C22: 2 | D22: category | E22: category_chart | F22: Number of Users | G22: Users | H22: 51-60 | J22: 2024-Q4 | K22: native | L22: 176600 | M22: count | N22: 176.6 K
A23: 2024-Q4 | B23: cliq | C23: 2 | D23: category | E23: category_chart | F23: Number of Users | G23: Users | H23: 61-70 | J23: 2024-Q4 | K23: native | L23: 78100 | M23: count | N23: 78.1 K
A24: 2024-Q4 | B24: cliq | C24: 2 | D24: category | E24: category_chart | F24: Number of Users | G24: Users | H24: 71-80 | J24: 2024-Q4 | K24: native | L24: 20100 | M24: count | N24: 20.1 K
A25: 2024-Q4 | B25: cliq | C25: 2 | D25: category | E25: category_chart | F25: Number of Users | G25: Users | H25: 81-90 | J25: 2024-Q4 | K25: native | L25: 4000 | M25: count | N25: 4.0 K
A26: 2024-Q4 | B26: cliq | C26: 2 | D26: category | E26: category_chart | F26: Number of Users | G26: Users | H26: <18 | J26: 2024-Q4 | K26: native | L26: 6200 | M26: count | N26: 6.2 K
A27: 2024-Q4 | B27: cliq | C27: 2 | D27: category | E27: category_chart | F27: Number of Users | G27: Users | H27: Female | J27: 2024-Q4 | K27: native | L27: 583100 | M27: count | N27: 583.1 K
A28: 2024-Q4 | B28: cliq | C28: 2 | D28: category | E28: category_chart | F28: Number of Users | G28: Users | H28: Individual | J28: 2024-Q4 | K28: native | L28: 1640000 | M28: count | N28: 1.64 M
A29: 2024-Q4 | B29: cliq | C29: 2 | D29: category | E29: category_chart | F29: Number of Users | G29: Users | H29: Jordanian | J29: 2024-Q4 | K29: native | L29: 1610000 | M29: count | N29: 1.61 M
A30: 2024-Q4 | B30: cliq | C30: 2 | D30: category | E30: category_chart | F30: Number of Users | G30: Users | H30: Legal (entities) | J30: 2024-Q4 | K30: native | L30: 30400 | M30: count | N30: 30.4 K
... A32: 2024-Q4 | B32: cliq | C32: 2 | D32: category | E32: category_chart | F32: Number of Users | G32: Users | H32: Non-Jordanian | J32: 2024-Q4 | K32: native | L32: 61000 | M32: count | N32: 61.0 K
A33: 2024-Q4 | B33: cliq | C33: 2 | D33: chart_point | E33: trend_chart | F33: Number of Users | G33: Users | J33: 2024-Q1 | K33: trailing_chart_point | L33: 1330000 | M33: count | N33: 1.33 M | O33: TRUE | P33: restated | Q33: see the 2024-Q3 report's reading of 2024-Q1, marked newest
A34: 2024-Q4 | B34: cliq | C34: 2 | D34: chart_point | E34: trend_chart | F34: Number of Users | G34: Users | J34: 2024-Q2 | K34: trailing_chart_point | L34: 1430000 | M34: count | N34: 1.43 M | O34: TRUE | P34: restated | Q34: see the 2024-Q3 report's reading of 2024-Q2, marked newest
A35: 2024-Q4 | B35: cliq | C35: 2 | D35: chart_point | E35: trend_chart | F35: Number of Users | G35: Users | J35: 2024-Q3 | K35: trailing_chart_point | L35: 1560000 | M35: count | N35: 1.56 M | O35: TRUE | P35: restated
A36: 2024-Q4 | B36: cliq | C36: 2 | D36: kpi | E36: stat_box | F36: Number of Users | G36: Users | J36: 2024-Q4 | K36: native | L36: 1670000 | M36: count | N36: 1.67 M
A37: 2025-Q1 | B37: cliq | C37: 2 | D37: category | E37: category_chart | F37: Number of Users | G37: Users | H37: 18-30 | J37: 2025-Q1 | K37: native | L37: 657000 | M37: count | N37: 657.0 K
A38: 2025-Q1 | B38: cliq | C38: 2 | D38: category | E38: category_chart | F38: Number of Users | G38: Users | H38: 31-40 | J38: 2025-Q1 | K38: native | L38: 465900 | M38: count | N38: 465.9 K
A39: 2025-Q1 | B39: cliq | C39: 2 | D39: category | E39: category_chart | F39: Number of Users | G39: Users | H39: 41-50 | J39: 2025-Q1 | K39: native | L39: 311700 | M39: count | N39: 311.7 K
A40: 2025-Q1 | B40: cliq | C40: 2 | D40: category | E40: category_chart | F40: Number of Users | G40: Users | H40: 51-60 | J40: 2025-Q1 | K40: native | L40: 190700 | M40: count | N40: 190.7 K
A41: 2025-Q1 | B41: cliq | C41: 2 | D41: category | E41: category_chart | F41: Number of Users | G41: Users | H41: 61-70 | J41: 2025-Q1 | K41: native | L41: 85500 | M41: count | N41: 85.5 K
A42: 2025-Q1 | B42: cliq | C42: 2 | D42: category | E42: category_chart | F42: Number of Users | G42: Users | H42: 71-80 | J42: 2025-Q1 | K42: native | L42: 22100 | M42: count | N42: 22.1 K
...

Sheet pivot
A2: period_scope | B2: native
A3: system | B3: ach
A4: metric | B4: (All)
A6: Sum of value | B6: Column Labels
A7: Row Labels | B7: EUR | C7: GBP | D7: USD | E7: (blank) | F7: Grand Total
A8: 2024-Q3 | B8: 9300901 | C8: 1000116 | D8: 119317056 | E8: 2362800000 | F8: 2492418073
A9: 2024-Q4 | B9: 8200941 | C9: 900113 | D9: 117217543 | E9: 2422970000 | F9: 2549288597
A10: 2025-Q1 | B10: 8901003 | C10: 1100107 | D10: 113016918 | E10: 2412980000 | F10: 2535998028
A11: 2025-Q2 | B11: 7900844 | C11: 900086 | D11: 110017236 | E11: 2352870000 | F11: 2471688166
A12: 2025-Q3 | B12: 9300989 | C12: 1100133 | D12: 123017556 | E12: 2613060000 | F12: 2746478678
A13: 2025-Q4 | B13: 7900922 | C13: 1000120 | D13: 122018897 | E13: 2633260000 | F13: 2764179939
A14: 2026-Q1 | B14: 7800828 | C14: 1000103 | D14: 112016863 | E14: 2693240000 | F14: 2814057794
A15: 2026-Q2 | B15: 8300898 | C15: 900113 | D15: 116017329 | E15: 2753290000 | F15: 2878508340
A16: Grand Total | B16: 67607326 | C16: 7900891 | D16: 932639398 | E16: 20244470000 | F16: 21252617615

Sheet Charts

Sheet IPS
A1: CliQ & JoMoPay Interoperability - Quarterly Data (Q3 2024 - Q2 2026)
A3: Category | B3: Metric | C3: Q3 2024 | D3: Q4 2024 | E3: Q1 2025 | F3: Q2 2025 | G3: Q3 2025 | H3: Q4 2025 | I3: Q1 2026 | J3: Q2 2026
A4: USERS
A5: Users | B5: Total Registered Users | C5: =SUM(CliQ!C5, JoMoPay!C5) -> 3890000 | D5: =SUM(CliQ!D5, JoMoPay!D5) -> 4260000 | E5: =SUM(CliQ!E5, JoMoPay!E5) -> 4380000 | F5: =SUM(CliQ!F5, JoMoPay!F5) -> 4550000 | G5: =SUM(CliQ!G5, JoMoPay!G5) -> 4700000 | H5: =SUM(CliQ!H5, JoMoPay!H5) -> 4940000 | I5: =SUM(CliQ!I5, JoMoPay!I5) -> 5130000 | J5: =SUM(CliQ!J5, JoMoPay!J5) -> 5310000
A6: USERS BY NATIONALITY
A7: Nationality | B7: Jordanian (count) | C7: =SUM(CliQ!C7,JoMoPay!C7) -> 3550000 | D7: =SUM(CliQ!D7,JoMoPay!D7) -> 3900000 | E7: =SUM(CliQ!E7,JoMoPay!E7) -> 4000000 | F7: =SUM(CliQ!F7,JoMoPay!F7) -> 4160000 | G7: =SUM(CliQ!G7,JoMoPay!G7) -> 4300000 | H7: =SUM(CliQ!H7,JoMoPay!H7) -> 4510000 | I7: =SUM(CliQ!I7,JoMoPay!I7) -> 4680000 | J7: =SUM(CliQ!J7,JoMoPay!J7) -> 4850000
A8: Nationality | B8: Jordanian (% of users) | C8: =C$7/(C$7+C$9) -> 0.91377091 | D8: =D$7/(D$7+D$9) -> 0.9152781 | E8: =E$7/(E$7+E$9) -> 0.91386795 | F8: =F$7/(F$7+F$9) -> 0.91392416 | G8: =G$7/(G$7+G$9) -> 0.913339 | H8: =H$7/(H$7+H$9) -> 0.91406567 | I8: =I$7/(I$7+I$9) -> 0.91242299 | J8: =J$7/(J$7+J$9) -> 0.91259761
A9: Nationality | B9: Non-Jordanian (count) | C9: =SUM(CliQ!C9,JoMoPay!C9) -> 335000 | D9: =SUM(CliQ!D9,JoMoPay!D9) -> 361000 | E9: =SUM(CliQ!E9,JoMoPay!E9) -> 377000 | F9: =SUM(CliQ!F9,JoMoPay!F9) -> 391800 | G9: =SUM(CliQ!G9,JoMoPay!G9) -> 408000 | H9: =SUM(CliQ!H9,JoMoPay!H9) -> 424000 | I9: =SUM(CliQ!I9,JoMoPay!I9) -> 449200 | J9: =SUM(CliQ!J9,JoMoPay!J9) -> 464500
A10: Nationality | B10: Non-Jordanian (% of users) | C10: =C$9/(C$9+C$7) -> 0.086229086 | D10: =D$9/(D$9+D$7) -> 0.084721896 | E10: =E$9/(E$9+E$7) -> 0.086132054 | F10: =F$9/(F$9+F$7) -> 0.086075838 | G10: =G$9/(G$9+G$7) -> 0.086661003 | H10: =H$9/(H$9+H$7) -> 0.085934333 | I10: =I$9/(I$9+I$7) -> 0.08757701 | J10: =J$9/(J$9+J$7) -> 0.08740239
A11: USERS BY GENDER
A12: Gender | B12: Male (count) | C12: =SUM(CliQ!C12,JoMoPay!C12) -> 2153400 | D12: =SUM(CliQ!D12,JoMoPay!D12) -> 2350000 | E12: =SUM(CliQ!E12,JoMoPay!E12) -> 2410000 | F12: =SUM(CliQ!F12,JoMoPay!F12) -> 2520000 | G12: =SUM(CliQ!G12,JoMoPay!G12) -> 2650000 | H12: =SUM(CliQ!H12,JoMoPay!H12) -> 2790000 | I12: =SUM(CliQ!I12,JoMoPay!I12) -> 2900000 | J12: =SUM(CliQ!J12,JoMoPay!J12) -> 3020000
A13: Gender | B13: Male (%) | C13: =C$12/(C$12+C$14) -> 0.56155631 | D13: =D$12/(D$12+D$14) -> 0.56044454 | E13: =E$12/(E$12+E$14) -> 0.55617096 | F13: =F$12/(F$12+F$14) -> 0.56360709 | G13: =G$12/(G$12+G$14) -> 0.57119455 | H13: =H$12/(H$12+H$14) -> 0.57247209 | I13: =I$12/(I$12+I$14) -> 0.57498612 | J13: =J$12/(J$12+J$14) -> 0.57733851
A14: Gender | B14: Female (count) | C14: =SUM(CliQ!C14,JoMoPay!C14) -> 1681300 | D14: =SUM(CliQ!D14,JoMoPay!D14) -> 1843100 | E14: =SUM(CliQ!E14,JoMoPay!E14) -> 1923200 | F14: =SUM(CliQ!F14,JoMoPay!F14) -> 1951200 | G14: =SUM(CliQ!G14,JoMoPay!G14) -> 1989400 | H14: =SUM(CliQ!H14,JoMoPay!H14) -> 2083600 | I14: =SUM(CliQ!I14,JoMoPay!I14) -> 2143600 | J14: =SUM(CliQ!J14,JoMoPay!J14) -> 2210900
A15: Gender | B15: Female (%) | C15: =C$14/(C$14+C$12) -> 0.43844369 | D15: =D$14/(D$14+D$12) -> 0.43955546 | E15: =E$14/(E$14+E$12) -> 0.44382904 | F15: =F$14/(F$14+F$12) -> 0.43639291 | G15: =G$14/(G$14+G$12) -> 0.42880545 | H15: =H$14/(H$14+H$12) -> 0.42752791 | I15: =I$14/(I$14+I$12) -> 0.42501388 | J15: =J$14/(J$14+J$12) -> 0.42266149
A16: USERS BY AGE BRACKET (count)
A17: Age | B17: <18 | C17: =SUM(CliQ!C17,JoMoPay!C17) -> 7200 | D17: =SUM(CliQ!D17,JoMoPay!D17) -> 7700 | E17: =SUM(CliQ!E17,JoMoPay!E17) -> 8000 | F17: =SUM(CliQ!F17,JoMoPay!F17) -> 9600 | G17: =SUM(CliQ!G17,JoMoPay!G17) -> 10200 | H17: =SUM(CliQ!H17,JoMoPay!H17) -> 10800 | I17: =SUM(CliQ!I17,JoMoPay!I17) -> 11400 | J17: =SUM(CliQ!J17,JoMoPay!J17) -> 12030
A18: Age | B18: 18-30 | C18: =SUM(CliQ!C18,JoMoPay!C18) -> 1419200 | D18: =SUM(CliQ!D18,JoMoPay!D18) -> 1597400 | E18: =SUM(CliQ!E18,JoMoPay!E18) -> 1595100 | F18: =SUM(CliQ!F18,JoMoPay!F18) -> 1636100 | G18: =SUM(CliQ!G18,JoMoPay!G18) -> 1706200 | H18: =SUM(CliQ!H18,JoMoPay!H18) -> 1805500 | I18: =SUM(CliQ!I18,JoMoPay!I18) -> 1845100 | J18: =SUM(CliQ!J18,JoMoPay!J18) -> 1896500
A19: Age | B19: 31-40 | C19: =SUM(CliQ!C19,JoMoPay!C19) -> 1012400 | D19: =SUM(CliQ!D19,JoMoPay!D19) -> 1105000 | E19: =SUM(CliQ!E19,JoMoPay!E19) -> 1134400 | F19: =SUM(CliQ!F19,JoMoPay!F19) -> 1175800 | G19: =SUM(CliQ!G19,JoMoPay!G19) -> 1209600 | H19: =SUM(CliQ!H19,JoMoPay!H19) -> 1261700 | I19: =SUM(CliQ!I19,JoMoPay!I19) -> 1313000 | J19: =SUM(CliQ!J19,JoMoPay!J19) -> 1357400
A20: Age | B20: 41-50 | C20: =SUM(CliQ!C20,JoMoPay!C20) -> 723000 | D20: =SUM(CliQ!D20,JoMoPay!D20) -> 792100 | E20: =SUM(CliQ!E20,JoMoPay!E20) -> 816200 | F20: =SUM(CliQ!F20,JoMoPay!F20) -> 850400 | G20: =SUM(CliQ!G20,JoMoPay!G20) -> 875900 | H20: =SUM(CliQ!H20,JoMoPay!H20) -> 915300 | I20: =SUM(CliQ!I20,JoMoPay!I20) -> 957000 | J20: =SUM(CliQ!J20,JoMoPay!J20) -> 992800
A21: Age | B21: 51-60 | C21: =SUM(CliQ!C21,JoMoPay!C21) -> 447600 | D21: =SUM(CliQ!D21,JoMoPay!D21) -> 494900 | E21: =SUM(CliQ!E21,JoMoPay!E21) -> 507700 | F21: =SUM(CliQ!F21,JoMoPay!F21) -> 530100 | G21: =SUM(CliQ!G21,JoMoPay!G21) -> 543600 | H21: =SUM(CliQ!H21,JoMoPay!H21) -> 570900 | I21: =SUM(CliQ!I21,JoMoPay!I21) -> 598300 | J21: =SUM(CliQ!J21,JoMoPay!J21) -> 622500
A22: Age | B22: 61-70 | C22: =SUM(CliQ!C22,JoMoPay!C22) -> 174000 | D22: =SUM(CliQ!D22,JoMoPay!D22) -> 196800 | E22: =SUM(CliQ!E22,JoMoPay!E22) -> 203900 | F22: =SUM(CliQ!F22,JoMoPay!F22) -> 215500 | G22: =SUM(CliQ!G22,JoMoPay!G22) -> 222800 | H22: =SUM(CliQ!H22,JoMoPay!H22) -> 236100 | I22: =SUM(CliQ!I22,JoMoPay!I22) -> 253500 | J22: =SUM(CliQ!J22,JoMoPay!J22) -> 267800
A23: Age | B23: 71-80 | C23: =SUM(CliQ!C23,JoMoPay!C23) -> 52500 | D23: =SUM(CliQ!D23,JoMoPay!D23) -> 59900 | E23: =SUM(CliQ!E23,JoMoPay!E23) -> 59000 | F23: =SUM(CliQ!F23,JoMoPay!F23) -> 61700 | G23: =SUM(CliQ!G23,JoMoPay!G23) -> 62300 | H23: =SUM(CliQ!H23,JoMoPay!H23) -> 66400 | I23: =SUM(CliQ!I23,JoMoPay!I23) -> 71300 | J23: =SUM(CliQ!J23,JoMoPay!J23) -> 75400
A24: Age | B24: 81-90 | C24: =SUM(CliQ!C24,JoMoPay!C24) -> 16300 | D24: =SUM(CliQ!D24,JoMoPay!D24) -> 18400 | E24: =SUM(CliQ!E24,JoMoPay!E24) -> 16500 | F24: =SUM(CliQ!F24,JoMoPay!F24) -> 19400 | G24: =SUM(CliQ!G24,JoMoPay!G24) -> 18700 | H24: =SUM(CliQ!H24,JoMoPay!H24) -> 19400 | I24: =SUM(CliQ!I24,JoMoPay!I24) -> 20300 | J24: =SUM(CliQ!J24,JoMoPay!J24) -> 23400
A25: TRANSACTIONS BY TYPE (Value, JOD)
A26: Txn Type (JOD) | B26: Money Transfer (JOD) | C26: =SUM(CliQ!C40,JoMoPay!C44) -> 3980000000 | D26: =SUM(CliQ!D40,JoMoPay!D44) -> 4240000000 | E26: =SUM(CliQ!E40,JoMoPay!E44) -> 4660000000 | F26: =SUM(CliQ!F40,JoMoPay!F44) -> 5100000000 | G26: =SUM(CliQ!G40,JoMoPay!G44) -> 5550000000 | H26: =SUM(CliQ!H40,JoMoPay!H44) -> 5320000000 | I26: =SUM(CliQ!I40,JoMoPay!I44) -> 5630000000 | J26: =SUM(CliQ!J40,JoMoPay!J44) -> 6000000000
A27: Txn Type (JOD) | B27: Money Transfer (%) | C27: =C$26/(C$26+C$28) -> 0.855546 | D27: =D$26/(D$26+D$28) -> 0.85021055 | E27: =E$26/(E$26+E$28) -> 0.84974471 | F27: =F$26/(F$26+F$28) -> 0.83170254 | G27: =G$26/(G$26+G$28) -> 0.77008464 | H27: =H$26/(H$26+H$28) -> 0.75173096 | I27: =I$26/(I$26+I$28) -> 0.75499531 | J27: =J$26/(J$26+J$28) -> 0.74037512
A28: Txn Type (JOD) | B28: Purchases (JOD) | C28: =SUM(CliQ!C42,JoMoPay!C46) -> 672000000 | D28: =SUM(CliQ!D42,JoMoPay!D46) -> 747000000 | E28: =SUM(CliQ!E42,JoMoPay!E46) -> 824000000 | F28: =SUM(CliQ!F42,JoMoPay!F46) -> 1032000000 | G28: =SUM(CliQ!G42,JoMoPay!G46) -> 1657000000 | H28: =SUM(CliQ!H42,JoMoPay!H46) -> 1757000000 | I28: =SUM(CliQ!I42,JoMoPay!I46) -> 1827000000 | J28: =SUM(CliQ!J42,JoMoPay!J46) -> 2104000000
A29: Txn Type (JOD) | B29: Purchases (%) | C29: =C$28/(C$28+C$26) -> 0.144454 | D29: =D$28/(D$28+D$26) -> 0.14978945 | E29: =E$28/(E$28+E$26) -> 0.15025529 | F29: =F$28/(F$28+F$26) -> 0.16829746 | G29: =G$28/(G$28+G$26) -> 0.22991536 | H29: =H$28/(H$28+H$26) -> 0.24826904 | I29: =I$28/(I$28+I$26) -> 0.24500469 | J29: =J$28/(J$28+J$26) -> 0.25962488

Sheet CliQ_JoMoPay_Interop
A1: CliQ & JoMoPay Interoperability - Quarterly Data (Q3 2024 - Q2 2026)
A3: Category | B3: Metric | C3: Q3 2024 | D3: Q4 2024 | E3: Q1 2025 | F3: Q2 2025 | G3: Q3 2025 | H3: Q4 2025 | I3: Q1 2026 | J3: Q2 2026
A4: MONEY TRANSFER TRANSACTIONS - OVERVIEW
A5: Transactions | B5: Total Number of MT Transactions | C5: =SUMIFS(Data!$L:$L,Data!$B:$B,"interoperability",Data!$K:$K,"native",Data!$J:$J,RIGHT(C$3,4)&"-"&LEFT(C$3,2),Data!$F:$F,"Number of Money Transfer Transactions",Data!$H:$H,"",Data!$I:$I,"") -> 33740000 | D5: =SUMIFS(Data!$L:$L,Data!$B:$B,"interoperability",Data!$K:$K,"native",Data!$J:$J,RIGHT(D$3,4)&"-"&LEFT(D$3,2),Data!$F:$F,"Number of Money Transfer Transactions",Data!$H:$H,"",Data!$I:$I,"") -> 39800000 | E5: =SUMIFS(Data!$L:$L,Data!$B:$B,"interoperability",Data!$K:$K,"native",Data!$J:$J,RIGHT(E$3,4)&"-"&LEFT(E$3,2),Data!$F:$F,"Number of Money Transfer Transactions",Data!$H:$H,"",Data!$I:$I,"") -> 45770000 | F5: =SUMIFS(Data!$L:$L,Data!$B:$B,"interoperability",Data!$K:$K,"native",Data!$J:$J,RIGHT(F$3,4)&"-"&LEFT(F$3,2),Data!$F:$F,"Number of Money Transfer Transactions",Data!$H:$H,"",Data!$I:$I,"") -> 53880000 | G5: =SUMIFS(Data!$L:$L,Data!$B:$B,"interoperability",Data!$K:$K,"native",Data!$J:$J,RIGHT(G$3,4)&"-"&LEFT(G$3,2),Data!$F:$F,"Number of Money Transfer Transactions",Data!$H:$H,"",Data!$I:$I,"") -> 62230000 | H5: =SUMIFS(Data!$L:$L,Data!$B:$B,"interoperability",Data!$K:$K,"native",Data!$J:$J,RIGHT(H$3,4)&"-"&LEFT(H$3,2),Data!$F:$F,"Number of Money Transfer Transactions",Data!$H:$H,"",Data!$I:$I,"") -> 67090000 | I5: =SUMIFS(Data!$L:$L,Data!$B:$B,"interoperability",Data!$K:$K,"native",Data!$J:$J,RIGHT(I$3,4)&"-"&LEFT(I$3,2),Data!$F:$F,"Number of Money Transfer Transactions",Data!$H:$H,"",Data!$I:$I,"") -> 73120000 | J5: =SUMIFS(Data!$L:$L,Data!$B:$B,"interoperability",Data!$K:$K,"native",Data!$J:$J,RIGHT(J$3,4)&"-"&LEFT(J$3,2),Data!$F:$F,"Number of Money Transfer Transactions",Data!$H:$H,"",Data!$I:$I,"") -> 85550000
A6: Transactions | B6: Total Value of MT Transactions (JOD) | C6: =SUMIFS(Data!$L:$L,Data!$B:$B,"interoperability",Data!$K:$K,"native",Data!$J:$J,RIGHT(C$3,4)&"-"&LEFT(C$3,2),Data!$F:$F,"Value of Money Transfer Transactions",Data!$H:$H,"",Data!$I:$I,"") -> 3980000000 | D6: =SUMIFS(Data!$L:$L,Data!$B:$B,"interoperability",Data!$K:$K,"native",Data!$J:$J,RIGHT(D$3,4)&"-"&LEFT(D$3,2),Data!$F:$F,"Value of Money Transfer Transactions",Data!$H:$H,"",Data!$I:$I,"") -> 4240000000 | E6: =SUMIFS(Data!$L:$L,Data!$B:$B,"interoperability",Data!$K:$K,"native",Data!$J:$J,RIGHT(E$3,4)&"-"&LEFT(E$3,2),Data!$F:$F,"Value of Money Transfer Transactions",Data!$H:$H,"",Data!$I:$I,"") -> 4650000000 | F6: =SUMIFS(Data!$L:$L,Data!$B:$B,"interoperability",Data!$K:$K,"native",Data!$J:$J,RIGHT(F$3,4)&"-"&LEFT(F$3,2),Data!$F:$F,"Value of Money Transfer Transactions",Data!$H:$H,"",Data!$I:$I,"") -> 5090000000 | G6: =SUMIFS(Data!$L:$L,Data!$B:$B,"interoperability",Data!$K:$K,"native",Data!$J:$J,RIGHT(G$3,4)&"-"&LEFT(G$3,2),Data!$F:$F,"Value of Money Transfer Transactions",Data!$H:$H,"",Data!$I:$I,"") -> 5540000000 | H6: =SUMIFS(Data!$L:$L,Data!$B:$B,"interoperability",Data!$K:$K,"native",Data!$J:$J,RIGHT(H$3,4)&"-"&LEFT(H$3,2),Data!$F:$F,"Value of Money Transfer Transactions",Data!$H:$H,"",Data!$I:$I,"") -> 5310000000 | I6: =SUMIFS(Data!$L:$L,Data!$B:$B,"interoperability",Data!$K:$K,"native",Data!$J:$J,RIGHT(I$3,4)&"-"&LEFT(I$3,2),Data!$F:$F,"Value of Money Transfer Transactions",Data!$H:$H,"",Data!$I:$I,"") -> 5630000000 | J6: =SUMIFS(Data!$L:$L,Data!$B:$B,"interoperability",Data!$K:$K,"native",Data!$J:$J,RIGHT(J$3,4)&"-"&LEFT(J$3,2),Data!$F:$F,"Value of Money Transfer Transactions",Data!$H:$H,"",Data!$I:$I,"") -> 6000000000
A7: BY INSTITUTION (On Us / Off Us) - Number
A8: On/Off Us | B8: On Us (same financial institution) | C8: =SUMIFS(Data!$L:$L,Data!$B:$B,"interoperability",Data!$K:$K,"native",Data!$J:$J,RIGHT(C$3,4)&"-"&LEFT(C$3,2),Data!$F:$F,"Number of Money Transfer Transactions",Data!$H:$H,"On Us",Data!$I:$I,"") -> 8700000 | D8: =SUMIFS(Data!$L:$L,Data!$B:$B,"interoperability",Data!$K:$K,"native",Data!$J:$J,RIGHT(D$3,4)&"-"&LEFT(D$3,2),Data!$F:$F,"Number of Money Transfer Transactions",Data!$H:$H,"On Us",Data!$I:$I,"") -> 10130000 | E8: =SUMIFS(Data!$L:$L,Data!$B:$B,"interoperability",Data!$K:$K,"native",Data!$J:$J,RIGHT(E$3,4)&"-"&LEFT(E$3,2),Data!$F:$F,"Number of Money Transfer Transactions",Data!$H:$H,"On Us",Data!$I:$I,"") -> 11860000 | F8: =SUMIFS(Data!$L:$L,Data!$B:$B,"interoperability",Data!$K:$K,"native",Data!$J:$J,RIGHT(F$3,4)&"-"&LEFT(F$3,2),Data!$F:$F,"Number of Money Transfer Transactions",Data!$H:$H,"On Us",Data!$I:$I,"") -> 14180000 | G8: =SUMIFS(Data!$L:$L,Data!$B:$B,"interoperability",Data!$K:$K,"native",Data!$J:$J,RIGHT(G$3,4)&"-"&LEFT(G$3,2),Data!$F:$F,"Number of Money Transfer Transactions",Data!$H:$H,"On Us",Data!$I:$I,"") -> 16960000 | H8: =SUMIFS(Data!$L:$L,Data!$B:$B,"interoperability",Data!$K:$K,"native",Data!$J:$J,RIGHT(H$3,4)&"-"&LEFT(H$3,2),Data!$F:$F,"Number of Money Transfer Transactions",Data!$H:$H,"On Us",Data!$I:$I,"") -> 18380000 | I8: =SUMIFS(Data!$L:$L,Data!$B:$B,"interoperability",Data!$K:$K,"native",Data!$J:$J,RIGHT(I$3,4)&"-"&LEFT(I$3,2),Data!$F:$F,"Number of Money Transfer Transactions",Data!$H:$H,"On Us",Data!$I:$I,"") -> 21640000 | J8: =SUMIFS(Data!$L:$L,Data!$B:$B,"interoperability",Data!$K:$K,"native",Data!$J:$J,RIGHT(J$3,4)&"-"&LEFT(J$3,2),Data!$F:$F,"Number of Money Transfer Transactions",Data!$H:$H,"On Us",Data!$I:$I,"") -> 26000000
A9: On/Off Us | B9: On Us (%) | C9: =C$8/(C$8+C$10) -> 0.25785418 | D9: =D$8/(D$8+D$10) -> 0.25452261 | E9: =E$8/(E$8+E$10) -> 0.2591217 | F9: =F$8/(F$8+F$10) -> 0.26317743 | G9: =G$8/(G$8+G$10) -> 0.27253736 | H9: =H$8/(H$8+H$10) -> 0.27391952 | I9: =I$8/(I$8+I$10) -> 0.29591139 | J9: =J$8/(J$8+J$10) -> 0.30391584
A10: On/Off Us | B10: Off Us (different institutions) | C10: =SUMIFS(Data!$L:$L,Data!$B:$B,"interoperability",Data!$K:$K,"native",Data!$J:$J,RIGHT(C$3,4)&"-"&LEFT(C$3,2),Data!$F:$F,"Number of Money Transfer Transactions",Data!$H:$H,"Off Us",Data!$I:$I,"") -> 25040000 | D10: =SUMIFS(Data!$L:$L,Data!$B:$B,"interoperability",Data!$K:$K,"native",Data!$J:$J,RIGHT(D$3,4)&"-"&LEFT(D$3,2),Data!$F:$F,"Number of Money Transfer Transactions",Data!$H:$H,"Off Us",Data!$I:$I,"") -> 29670000 | E10: =SUMIFS(Data!$L:$L,Data!$B:$B,"interoperability",Data!$K:$K,"native",Data!$J:$J,RIGHT(E$3,4)&"-"&LEFT(E$3,2),Data!$F:$F,"Number of Money Transfer Transactions",Data!$H:$H,"Off Us",Data!$I:$I,"") -> 33910000 | F10: =SUMIFS(Data!$L:$L,Data!$B:$B,"interoperability",Data!$K:$K,"native",Data!$J:$J,RIGHT(F$3,4)&"-"&LEFT(F$3,2),Data!$F:$F,"Number of Money Transfer Transactions",Data!$H:$H,"Off Us",Data!$I:$I,"") -> 39700000 | G10: =SUMIFS(Data!$L:$L,Data!$B:$B,"interoperability",Data!$K:$K,"native",Data!$J:$J,RIGHT(G$3,4)&"-"&LEFT(G$3,2),Data!$F:$F,"Number of Money Transfer Transactions",Data!$H:$H,"Off Us",Data!$I:$I,"") -> 45270000 | H10: =SUMIFS(Data!$L:$L,Data!$B:$B,"interoperability",Data!$K:$K,"native",Data!$J:$J,RIGHT(H$3,4)&"-"&LEFT(H$3,2),Data!$F:$F,"Number of Money Transfer Transactions",Data!$H:$H,"Off Us",Data!$I:$I,"") -> 48720000 | I10: =SUMIFS(Data!$L:$L,Data!$B:$B,"interoperability",Data!$K:$K,"native",Data!$J:$J,RIGHT(I$3,4)&"-"&LEFT(I$3,2),Data!$F:$F,"Number of Money Transfer Transactions",Data!$H:$H,"Off Us",Data!$I:$I,"") -> 51490000 | J10: =SUMIFS(Data!$L:$L,Data!$B:$B,"interoperability",Data!$K:$K,"native",Data!$J:$J,RIGHT(J$3,4)&"-"&LEFT(J$3,2),Data!$F:$F,"Number of Money Transfer Transactions",Data!$H:$H,"Off Us",Data!$I:$I,"") -> 59550000
A11: On/Off Us | B11: Off Us (%) | C11: =C$10/(C$10+C$8) -> 0.74214582 | D11: =D$10/(D$10+D$8) -> 0.74547739 | E11: =E$10/(E$10+E$8) -> 0.7408783 | F11: =F$10/(F$10+F$8) -> 0.73682257 | G11: =G$10/(G$10+G$8) -> 0.72746264 | H11: =H$10/(H$10+H$8) -> 0.72608048 | I11: =I$10/(I$10+I$8) -> 0.70408861 | J11: =J$10/(J$10+J$8) -> 0.69608416
A12: BY INSTITUTION (On Us / Off Us) - Value, JOD
A13: On/Off Us (JOD) | B13: On Us (JOD) | C13: =SUMIFS(Data!$L:$L,Data!$B:$B,"interoperability",Data!$K:$K,"native",Data!$J:$J,RIGHT(C$3,4)&"-"&LEFT(C$3,2),Data!$F:$F,"Value of Money Transfer Transactions",Data!$H:$H,"On Us",Data!$I:$I,"") -> 777000000 | D13: =SUMIFS(Data!$L:$L,Data!$B:$B,"interoperability",Data!$K:$K,"native",Data!$J:$J,RIGHT(D$3,4)&"-"&LEFT(D$3,2),Data!$F:$F,"Value of Money Transfer Transactions",Data!$H:$H,"On Us",Data!$I:$I,"") -> 810000000 | E13: =SUMIFS(Data!$L:$L,Data!$B:$B,"interoperability",Data!$K:$K,"native",Data!$J:$J,RIGHT(E$3,4)&"-"&LEFT(E$3,2),Data!$F:$F,"Value of Money Transfer Transactions",Data!$H:$H,"On Us",Data!$I:$I,"") -> 909000000 | F13: =SUMIFS(Data!$L:$L,Data!$B:$B,"interoperability",Data!$K:$K,"native",Data!$J:$J,RIGHT(F$3,4)&"-"&LEFT(F$3,2),Data!$F:$F,"Value of Money Transfer Transactions",Data!$H:$H,"On Us",Data!$I:$I,"") -> 998000000 | G13: =SUMIFS(Data!$L:$L,Data!$B:$B,"interoperability",Data!$K:$K,"native",Data!$J:$J,RIGHT(G$3,4)&"-"&LEFT(G$3,2),Data!$F:$F,"Value of Money Transfer Transactions",Data!$H:$H,"On Us",Data!$I:$I,"") -> 1130000000 | H13: =SUMIFS(Data!$L:$L,Data!$B:$B,"interoperability",Data!$K:$K,"native",Data!$J:$J,RIGHT(H$3,4)&"-"&LEFT(H$3,2),Data!$F:$F,"Value of Money Transfer Transactions",Data!$H:$H,"On Us",Data!$I:$I,"") -> 1080000000 | I13: =SUMIFS(Data!$L:$L,Data!$B:$B,"interoperability",Data!$K:$K,"native",Data!$J:$J,RIGHT(I$3,4)&"-"&LEFT(I$3,2),Data!$F:$F,"Value of Money Transfer Transactions",Data!$H:$H,"On Us",Data!$I:$I,"") -> 1190000000 | J13: =SUMIFS(Data!$L:$L,Data!$B:$B,"interoperability",Data!$K:$K,"native",Data!$J:$J,RIGHT(J$3,4)&"-"&LEFT(J$3,2),Data!$F:$F,"Value of Money Transfer Transactions",Data!$H:$H,"On Us",Data!$I:$I,"") -> 1270000000
A14: On/Off Us (JOD) | B14: On Us (%) | C14: =C$13/(C$13+C$15) -> 0.1953734 | D14: =D$13/(D$13+D$15) -> 0.19103774 | E14: =E$13/(E$13+E$15) -> 0.19552592 | F14: =F$13/(F$13+F$15) -> 0.19576304 | G14: =G$13/(G$13+G$15) -> 0.20397112 | H14: =H$13/(H$13+H$15) -> 0.20300752 | I14: =I$13/(I$13+I$15) -> 0.21099291 | J14: =J$13/(J$13+J$15) -> 0.21166667
A15: On/Off Us (JOD) | B15: Off Us (JOD) | C15: =SUMIFS(Data!$L:$L,Data!$B:$B,"interoperability",Data!$K:$K,"native",Data!$J:$J,RIGHT(C$3,4)&"-"&LEFT(C$3,2),Data!$F:$F,"Value of Money Transfer Transactions",Data!$H:$H,"Off Us",Data!$I:$I,"") -> 3200000000 | D15: =SUMIFS(Data!$L:$L,Data!$B:$B,"interoperability",Data!$K:$K,"native",Data!$J:$J,RIGHT(D$3,4)&"-"&LEFT(D$3,2),Data!$F:$F,"Value of Money Transfer Transactions",Data!$H:$H,"Off Us",Data!$I:$I,"") -> 3430000000 | E15: =SUMIFS(Data!$L:$L,Data!$B:$B,"interoperability",Data!$K:$K,"native",Data!$J:$J,RIGHT(E$3,4)&"-"&LEFT(E$3,2),Data!$F:$F,"Value of Money Transfer Transactions",Data!$H:$H,"Off Us",Data!$I:$I,"") -> 3740000000 | F15: =SUMIFS(Data!$L:$L,Data!$B:$B,"interoperability",Data!$K:$K,"native",Data!$J:$J,RIGHT(F$3,4)&"-"&LEFT(F$3,2),Data!$F:$F,"Value of Money Transfer Transactions",Data!$H:$H,"Off Us",Data!$I:$I,"") -> 4100000000 | G15: =SUMIFS(Data!$L:$L,Data!$B:$B,"interoperability",Data!$K:$K,"native",Data!$J:$J,RIGHT(G$3,4)&"-"&LEFT(G$3,2),Data!$F:$F,"Value of Money Transfer Transactions",Data!$H:$H,"Off Us",Data!$I:$I,"") -> 4410000000 | H15: =SUMIFS(Data!$L:$L,Data!$B:$B,"interoperability",Data!$K:$K,"native",Data!$J:$J,RIGHT(H$3,4)&"-"&LEFT(H$3,2),Data!$F:$F,"Value of Money Transfer Transactions",Data!$H:$H,"Off Us",Data!$I:$I,"") -> 4240000000 | I15: =SUMIFS(Data!$L:$L,Data!$B:$B,"interoperability",Data!$K:$K,"native",Data!$J:$J,RIGHT(I$3,4)&"-"&LEFT(I$3,2),Data!$F:$F,"Value of Money Transfer Transactions",Data!$H:$H,"Off Us",Data!$I:$I,"") -> 4450000000 | J15: =SUMIFS(Data!$L:$L,Data!$B:$B,"interoperability",Data!$K:$K,"native",Data!$J:$J,RIGHT(J$3,4)&"-"&LEFT(J$3,2),Data!$F:$F,"Value of Money Transfer Transactions",Data!$H:$H,"Off Us",Data!$I:$I,"") -> 4730000000
A16: On/Off Us (JOD) | B16: Off Us (%) | C16: =C$15/(C$15+C$13) -> 0.8046266 | D16: =D$15/(D$15+D$13) -> 0.80896226 | E16: =E$15/(E$15+E$13) -> 0.80447408 | F16: =F$15/(F$15+F$13) -> 0.80423696 | G16: =G$15/(G$15+G$13) -> 0.79602888 | H16: =H$15/(H$15+H$13) -> 0.79699248 | I16: =I$15/(I$15+I$13) -> 0.78900709 | J16: =J$15/(J$15+J$13) -> 0.78833333
A17: BY DIRECTION (PSP<->Bank) - Number
A18: Direction | B18: mPSP to Bank | C18: =SUMIFS(Data!$L:$L,Data!$B:$B,"interoperability",Data!$K:$K,"native",Data!$J:$J,RIGHT(C$3,4)&"-"&LEFT(C$3,2),Data!$F:$F,"Number of Money Transfer Transactions",Data!$H:$H,"mPSP to Bank",Data!$I:$I,"") -> 4300000 | D18: =SUMIFS(Data!$L:$L,Data!$B:$B,"interoperability",Data!$K:$K,"native",Data!$J:$J,RIGHT(D$3,4)&"-"&LEFT(D$3,2),Data!$F:$F,"Number of Money Transfer Transactions",Data!$H:$H,"mPSP to Bank",Data!$I:$I,"") -> 5200000 | E18: =SUMIFS(Data!$L:$L,Data!$B:$B,"interoperability",Data!$K:$K,"native",Data!$J:$J,RIGHT(E$3,4)&"-"&LEFT(E$3,2),Data!$F:$F,"Number of Money Transfer Transactions",Data!$H:$H,"mPSP to Bank",Data!$I:$I,"") -> 5900000 | F18: =SUMIFS(Data!$L:$L,Data!$B:$B,"interoperability",Data!$K:$K,"native",Data!$J:$J,RIGHT(F$3,4)&"-"&LEFT(F$3,2),Data!$F:$F,"Number of Money Transfer Transactions",Data!$H:$H,"mPSP to Bank",Data!$I:$I,"") -> 7100000 | G18: =SUMIFS(Data!$L:$L,Data!$B:$B,"interoperability",Data!$K:$K,"native",Data!$J:$J,RIGHT(G$3,4)&"-"&LEFT(G$3,2),Data!$F:$F,"Number of Money Transfer Transactions",Data!$H:$H,"mPSP to Bank",Data!$I:$I,"") -> 8100000 | H18: =SUMIFS(Data!$L:$L,Data!$B:$B,"interoperability",Data!$K:$K,"native",Data!$J:$J,RIGHT(H$3,4)&"-"&LEFT(H$3,2),Data!$F:$F,"Number of Money Transfer Transactions",Data!$H:$H,"mPSP to Bank",Data!$I:$I,"") -> 8500000 | I18: =SUMIFS(Data!$L:$L,Data!$B:$B,"interoperability",Data!$K:$K,"native",Data!$J:$J,RIGHT(I$3,4)&"-"&LEFT(I$3,2),Data!$F:$F,"Number of Money Transfer Transactions",Data!$H:$H,"mPSP to Bank",Data!$I:$I,"") -> 8900000 | J18: =SUMIFS(Data!$L:$L,Data!$B:$B,"interoperability",Data!$K:$K,"native",Data!$J:$J,RIGHT(J$3,4)&"-"&LEFT(J$3,2),Data!$F:$F,"Number of Money Transfer Transactions",Data!$H:$H,"mPSP to Bank",Data!$I:$I,"") -> 10500000
A19: Direction | B19: mPSP to Bank (%) | C19: =C$18/(C$18+C$20) -> 0.45263158 | D19: =D$18/(D$18+D$20) -> 0.44827586 | E19: =E$18/(E$18+E$20) -> 0.43382353 | F19: =F$18/(F$18+F$20) -> 0.43030303 | G19: =G$18/(G$18+G$20) -> 0.421875 | H19: =H$18/(H$18+H$20) -> 0.41062802 | I19: =I$18/(I$18+I$20) -> 0.40454545 | J19: =J$18/(J$18+J$20) -> 0.40229885
A20: Direction | B20: Bank to mPSP | C20: =SUMIFS(Data!$L:$L,Data!$B:$B,"interoperability",Data!$K:$K,"native",Data!$J:$J,RIGHT(C$3,4)&"-"&LEFT(C$3,2),Data!$F:$F,"Number of Money Transfer Transactions",Data!$H:$H,"Bank to mPSP",Data!$I:$I,"") -> 5200000 | D20: =SUMIFS(Data!$L:$L,Data!$B:$B,"interoperability",Data!$K:$K,"native",Data!$J:$J,RIGHT(D$3,4)&"-"&LEFT(D$3,2),Data!$F:$F,"Number of Money Transfer Transactions",Data!$H:$H,"Bank to mPSP",Data!$I:$I,"") -> 6400000 | E20: =SUMIFS(Data!$L:$L,Data!$B:$B,"interoperability",Data!$K:$K,"native",Data!$J:$J,RIGHT(E$3,4)&"-"&LEFT(E$3,2),Data!$F:$F,"Number of Money Transfer Transactions",Data!$H:$H,"Bank to mPSP",Data!$I:$I,"") -> 7700000 | F20: =SUMIFS(Data!$L:$L,Data!$B:$B,"interoperability",Data!$K:$K,"native",Data!$J:$J,RIGHT(F$3,4)&"-"&LEFT(F$3,2),Data!$F:$F,"Number of Money Transfer Transactions",Data!$H:$H,"Bank to mPSP",Data!$I:$I,"") -> 9400000 | G20: =SUMIFS(Data!$L:$L,Data!$B:$B,"interoperability",Data!$K:$K,"native",Data!$J:$J,RIGHT(G$3,4)&"-"&LEFT(G$3,2),Data!$F:$F,"Number of Money Transfer Transactions",Data!$H:$H,"Bank to mPSP",Data!$I:$I,"") -> 11100000 | H20: =SUMIFS(Data!$L:$L,Data!$B:$B,"interoperability",Data!$K:$K,"native",Data!$J:$J,RIGHT(H$3,4)&"-"&LEFT(H$3,2),Data!$F:$F,"Number of Money Transfer Transactions",Data!$H:$H,"Bank to mPSP",Data!$I:$I,"") -> 12200000 | I20: =SUMIFS(Data!$L:$L,Data!$B:$B,"interoperability",Data!$K:$K,"native",Data!$J:$J,RIGHT(I$3,4)&"-"&LEFT(I$3,2),Data!$F:$F,"Number of Money Transfer Transactions",Data!$H:$H,"Bank to mPSP",Data!$I:$I,"") -> 13100000 | J20: =SUMIFS(Data!$L:$L,Data!$B:$B,"interoperability",Data!$K:$K,"native",Data!$J:$J,RIGHT(J$3,4)&"-"&LEFT(J$3,2),Data!$F:$F,"Number of Money Transfer Transactions",Data!$H:$H,"Bank to mPSP",Data!$I:$I,"") -> 15600000
A21: Direction | B21: Bank to mPSP (%) | C21: =C$20/(C$20+C$18) -> 0.54736842 | D21: =D$20/(D$20+D$18) -> 0.55172414 | E21: =E$20/(E$20+E$18) -> 0.56617647 | F21: =F$20/(F$20+F$18) -> 0.56969697 | G21: =G$20/(G$20+G$18) -> 0.578125 | H21: =H$20/(H$20+H$18) -> 0.58937198 | I21: =I$20/(I$20+I$18) -> 0.59545455 | J21: =J$20/(J$20+J$18) -> 0.59770115
A22: BY DIRECTION (PSP<->Bank) - Value, JOD
A23: Direction (JOD) | B23: mPSP to Bank (JOD) | C23: =SUMIFS(Data!$L:$L,Data!$B:$B,"interoperability",Data!$K:$K,"native",Data!$J:$J,RIGHT(C$3,4)&"-"&LEFT(C$3,2),Data!$F:$F,"Value of Money Transfer Transactions",Data!$H:$H,"mPSP to Bank",Data!$I:$I,"") -> 615000000 | D23: =SUMIFS(Data!$L:$L,Data!$B:$B,"interoperability",Data!$K:$K,"native",Data!$J:$J,RIGHT(D$3,4)&"-"&LEFT(D$3,2),Data!$F:$F,"Value of Money Transfer Transactions",Data!$H:$H,"mPSP to Bank",Data!$I:$I,"") -> 661000000 | E23: =SUMIFS(Data!$L:$L,Data!$B:$B,"interoperability",Data!$K:$K,"native",Data!$J:$J,RIGHT(E$3,4)&"-"&LEFT(E$3,2),Data!$F:$F,"Value of Money Transfer Transactions",Data!$H:$H,"mPSP to Bank",Data!$I:$I,"") -> 698000000 | F23: =SUMIFS(Data!$L:$L,Data!$B:$B,"interoperability",Data!$K:$K,"native",Data!$J:$J,RIGHT(F$3,4)&"-"&LEFT(F$3,2),Data!$F:$F,"Value of Money Transfer Transactions",Data!$H:$H,"mPSP to Bank",Data!$I:$I,"") -> 758000000 | G23: =SUMIFS(Data!$L:$L,Data!$B:$B,"interoperability",Data!$K:$K,"native",Data!$J:$J,RIGHT(G$3,4)&"-"&LEFT(G$3,2),Data!$F:$F,"Value of Money Transfer Transactions",Data!$H:$H,"mPSP to Bank",Data!$I:$I,"") -> 805000000 | H23: =SUMIFS(Data!$L:$L,Data!$B:$B,"interoperability",Data!$K:$K,"native",Data!$J:$J,RIGHT(H$3,4)&"-"&LEFT(H$3,2),Data!$F:$F,"Value of Money Transfer Transactions",Data!$H:$H,"mPSP to Bank",Data!$I:$I,"") -> 712000000 | I23: =SUMIFS(Data!$L:$L,Data!$B:$B,"interoperability",Data!$K:$K,"native",Data!$J:$J,RIGHT(I$3,4)&"-"&LEFT(I$3,2),Data!$F:$F,"Value of Money Transfer Transactions",Data!$H:$H,"mPSP to Bank",Data!$I:$I,"") -> 721000000 | J23: =SUMIFS(Data!$L:$L,Data!$B:$B,"interoperability",Data!$K:$K,"native",Data!$J:$J,RIGHT(J$3,4)&"-"&LEFT(J$3,2),Data!$F:$F,"Value of Money Transfer Transactions",Data!$H:$H,"mPSP to Bank",Data!$I:$I,"") -> 794000000
A24: Direction (JOD) | B24: mPSP to Bank (%) | C24: =C$23/(C$23+C$25) -> 0.60531496 | D24: =D$23/(D$23+D$25) -> 0.61034164 | E24: =E$23/(E$23+E$25) -> 0.59353741 | F24: =F$23/(F$23+F$25) -> 0.58578053 | G24: =G$23/(G$23+G$25) -> 0.57664756 | H24: =H$23/(H$23+H$25) -> 0.55108359 | I24: =I$23/(I$23+I$25) -> 0.54374057 | J24: =J$23/(J$23+J$25) -> 0.54272044
A25: Direction (JOD) | B25: Bank to mPSP (JOD) | C25: =SUMIFS(Data!$L:$L,Data!$B:$B,"interoperability",Data!$K:$K,"native",Data!$J:$J,RIGHT(C$3,4)&"-"&LEFT(C$3,2),Data!$F:$F,"Value of Money Transfer Transactions",Data!$H:$H,"Bank to mPSP",Data!$I:$I,"") -> 401000000 | D25: =SUMIFS(Data!$L:$L,Data!$B:$B,"interoperability",Data!$K:$K,"native",Data!$J:$J,RIGHT(D$3,4)&"-"&LEFT(D$3,2),Data!$F:$F,"Value of Money Transfer Transactions",Data!$H:$H,"Bank to mPSP",Data!$I:$I,"") -> 422000000 | E25: =SUMIFS(Data!$L:$L,Data!$B:$B,"interoperability",Data!$K:$K,"native",Data!$J:$J,RIGHT(E$3,4)&"-"&LEFT(E$3,2),Data!$F:$F,"Value of Money Transfer Transactions",Data!$H:$H,"Bank to mPSP",Data!$I:$I,"") -> 478000000 | F25: =SUMIFS(Data!$L:$L,Data!$B:$B,"interoperability",Data!$K:$K,"native",Data!$J:$J,RIGHT(F$3,4)&"-"&LEFT(F$3,2),Data!$F:$F,"Value of Money Transfer Transactions",Data!$H:$H,"Bank to mPSP",Data!$I:$I,"") -> 536000000 | G25: =SUMIFS(Data!$L:$L,Data!$B:$B,"interoperability",Data!$K:$K,"native",Data!$J:$J,RIGHT(G$3,4)&"-"&LEFT(G$3,2),Data!$F:$F,"Value of Money Transfer Transactions",Data!$H:$H,"Bank to mPSP",Data!$I:$I,"") -> 591000000 | H25: =SUMIFS(Data!$L:$L,Data!$B:$B,"interoperability",Data!$K:$K,"native",Data!$J:$J,RIGHT(H$3,4)&"-"&LEFT(H$3,2),Data!$F:$F,"Value of Money Transfer Transactions",Data!$H:$H,"Bank to mPSP",Data!$I:$I,"") -> 580000000 | I25: =SUMIFS(Data!$L:$L,Data!$B:$B,"interoperability",Data!$K:$K,"native",Data!$J:$J,RIGHT(I$3,4)&"-"&LEFT(I$3,2),Data!$F:$F,"Value of Money Transfer Transactions",Data!$H:$H,"Bank to mPSP",Data!$I:$I,"") -> 605000000 | J25: =SUMIFS(Data!$L:$L,Data!$B:$B,"interoperability",Data!$K:$K,"native",Data!$J:$J,RIGHT(J$3,4)&"-"&LEFT(J$3,2),Data!$F:$F,"Value of Money Transfer Transactions",Data!$H:$H,"Bank to mPSP",Data!$I:$I,"") -> 669000000
A26: Direction (JOD) | B26: Bank to mPSP (%) | C26: =C$25/(C$25+C$23) -> 0.39468504 | D26: =D$25/(D$25+D$23) -> 0.38965836 | E26: =E$25/(E$25+E$23) -> 0.40646259 | F26: =F$25/(F$25+F$23) -> 0.41421947 | G26: =G$25/(G$25+G$23) -> 0.42335244 | H26: =H$25/(H$25+H$23) -> 0.44891641 | I26: =I$25/(I$25+I$23) -> 0.45625943 | J26: =J$25/(J$25+J$23) -> 0.45727956

Sheet CliQ
A1: CliQ (Instant Payments) - Quarterly Data (Q3 2024 - Q2 2026)
A3: Category | B3: Metric | C3: Q3 2024 | D3: Q4 2024 | E3: Q1 2025 | F3: Q2 2025 | G3: Q3 2025 | H3: Q4 2025 | I3: Q1 2026 | J3: Q2 2026
A4: USERS
A5: Users | B5: Total Registered Users | C5: =SUMIFS(Data!$L:$L,Data!$B:$B,"cliq",Data!$K:$K,"native",Data!$J:$J,RIGHT(C$3,4)&"-"&LEFT(C$3,2),Data!$F:$F,"Number of Users",Data!$H:$H,"",Data!$I:$I,"") -> 1560000 | D5: =SUMIFS(Data!$L:$L,Data!$B:$B,"cliq",Data!$K:$K,"native",Data!$J:$J,RIGHT(D$3,4)&"-"&LEFT(D$3,2),Data!$F:$F,"Number of Users",Data!$H:$H,"",Data!$I:$I,"") -> 1670000 | E5: =SUMIFS(Data!$L:$L,Data!$B:$B,"cliq",Data!$K:$K,"native",Data!$J:$J,RIGHT(E$3,4)&"-"&LEFT(E$3,2),Data!$F:$F,"Number of Users",Data!$H:$H,"",Data!$I:$I,"") -> 1780000 | F5: =SUMIFS(Data!$L:$L,Data!$B:$B,"cliq",Data!$K:$K,"native",Data!$J:$J,RIGHT(F$3,4)&"-"&LEFT(F$3,2),Data!$F:$F,"Number of Users",Data!$H:$H,"",Data!$I:$I,"") -> 1880000 | G5: =SUMIFS(Data!$L:$L,Data!$B:$B,"cliq",Data!$K:$K,"native",Data!$J:$J,RIGHT(G$3,4)&"-"&LEFT(G$3,2),Data!$F:$F,"Number of Users",Data!$H:$H,"",Data!$I:$I,"") -> 2000000 | H5: =SUMIFS(Data!$L:$L,Data!$B:$B,"cliq",Data!$K:$K,"native",Data!$J:$J,RIGHT(H$3,4)&"-"&LEFT(H$3,2),Data!$F:$F,"Number of Users",Data!$H:$H,"",Data!$I:$I,"") -> 2130000 | I5: =SUMIFS(Data!$L:$L,Data!$B:$B,"cliq",Data!$K:$K,"native",Data!$J:$J,RIGHT(I$3,4)&"-"&LEFT(I$3,2),Data!$F:$F,"Number of Users",Data!$H:$H,"",Data!$I:$I,"") -> 2220000 | J5: =SUMIFS(Data!$L:$L,Data!$B:$B,"cliq",Data!$K:$K,"native",Data!$J:$J,RIGHT(J$3,4)&"-"&LEFT(J$3,2),Data!$F:$F,"Number of Users",Data!$H:$H,"",Data!$I:$I,"") -> 2310000
A6: USERS BY NATIONALITY
A7: Nationality | B7: Jordanian (count) | C7: =SUMIFS(Data!$L:$L,Data!$B:$B,"cliq",Data!$K:$K,"native",Data!$J:$J,RIGHT(C$3,4)&"-"&LEFT(C$3,2),Data!$F:$F,"Number of Users",Data!$H:$H,"Jordanian",Data!$I:$I,"") -> 1500000 | D7: =SUMIFS(Data!$L:$L,Data!$B:$B,"cliq",Data!$K:$K,"native",Data!$J:$J,RIGHT(D$3,4)&"-"&LEFT(D$3,2),Data!$F:$F,"Number of Users",Data!$H:$H,"Jordanian",Data!$I:$I,"") -> 1610000 | E7: =SUMIFS(Data!$L:$L,Data!$B:$B,"cliq",Data!$K:$K,"native",Data!$J:$J,RIGHT(E$3,4)&"-"&LEFT(E$3,2),Data!$F:$F,"Number of Users",Data!$H:$H,"Jordanian",Data!$I:$I,"") -> 1710000 | F7: =SUMIFS(Data!$L:$L,Data!$B:$B,"cliq",Data!$K:$K,"native",Data!$J:$J,RIGHT(F$3,4)&"-"&LEFT(F$3,2),Data!$F:$F,"Number of Users",Data!$H:$H,"Jordanian",Data!$I:$I,"") -> 1810000 | G7: =SUMIFS(Data!$L:$L,Data!$B:$B,"cliq",Data!$K:$K,"native",Data!$J:$J,RIGHT(G$3,4)&"-"&LEFT(G$3,2),Data!$F:$F,"Number of Users",Data!$H:$H,"Jordanian",Data!$I:$I,"") -> 1930000 | H7: =SUMIFS(Data!$L:$L,Data!$B:$B,"cliq",Data!$K:$K,"native",Data!$J:$J,RIGHT(H$3,4)&"-"&LEFT(H$3,2),Data!$F:$F,"Number of Users",Data!$H:$H,"Jordanian",Data!$I:$I,"") -> 2040000 | I7: =SUMIFS(Data!$L:$L,Data!$B:$B,"cliq",Data!$K:$K,"native",Data!$J:$J,RIGHT(I$3,4)&"-"&LEFT(I$3,2),Data!$F:$F,"Number of Users",Data!$H:$H,"Jordanian",Data!$I:$I,"") -> 2130000 | J7: =SUMIFS(Data!$L:$L,Data!$B:$B,"cliq",Data!$K:$K,"native",Data!$J:$J,RIGHT(J$3,4)&"-"&LEFT(J$3,2),Data!$F:$F,"Number of Users",Data!$H:$H,"Jordanian",Data!$I:$I,"") -> 2220000
A8: Nationality | B8: Jordanian (% of users) | C8: =C$7/(C$7+C$9) -> 0.96463023 | D8: =D$7/(D$7+D$9) -> 0.96349491 | E8: =E$7/(E$7+E$9) -> 0.962296 | F8: =F$7/(F$7+F$9) -> 0.96184504 | G8: =G$7/(G$7+G$9) -> 0.96115538 | H8: =H$7/(H$7+H$9) -> 0.96045198 | I8: =I$7/(I$7+I$9) -> 0.95980534 | J8: =J$7/(J$7+J$9) -> 0.95917045
A9: Nationality | B9: Non-Jordanian (count) | C9: =SUMIFS(Data!$L:$L,Data!$B:$B,"cliq",Data!$K:$K,"native",Data!$J:$J,RIGHT(C$3,4)&"-"&LEFT(C$3,2),Data!$F:$F,"Number of Users",Data!$H:$H,"Non-Jordanian",Data!$I:$I,"") -> 55000 | D9: =SUMIFS(Data!$L:$L,Data!$B:$B,"cliq",Data!$K:$K,"native",Data!$J:$J,RIGHT(D$3,4)&"-"&LEFT(D$3,2),Data!$F:$F,"Number of Users",Data!$H:$H,"Non-Jordanian",Data!$I:$I,"") -> 61000 | E9: =SUMIFS(Data!$L:$L,Data!$B:$B,"cliq",Data!$K:$K,"native",Data!$J:$J,RIGHT(E$3,4)&"-"&LEFT(E$3,2),Data!$F:$F,"Number of Users",Data!$H:$H,"Non-Jordanian",Data!$I:$I,"") -> 67000 | F9: =SUMIFS(Data!$L:$L,Data!$B:$B,"cliq",Data!$K:$K,"native",Data!$J:$J,RIGHT(F$3,4)&"-"&LEFT(F$3,2),Data!$F:$F,"Number of Users",Data!$H:$H,"Non-Jordanian",Data!$I:$I,"") -> 71800 | G9: =SUMIFS(Data!$L:$L,Data!$B:$B,"cliq",Data!$K:$K,"native",Data!$J:$J,RIGHT(G$3,4)&"-"&LEFT(G$3,2),Data!$F:$F,"Number of Users",Data!$H:$H,"Non-Jordanian",Data!$I:$I,"") -> 78000 | H9: =SUMIFS(Data!$L:$L,Data!$B:$B,"cliq",Data!$K:$K,"native",Data!$J:$J,RIGHT(H$3,4)&"-"&LEFT(H$3,2),Data!$F:$F,"Number of Users",Data!$H:$H,"Non-Jordanian",Data!$I:$I,"") -> 84000 | I9: =SUMIFS(Data!$L:$L,Data!$B:$B,"cliq",Data!$K:$K,"native",Data!$J:$J,RIGHT(I$3,4)&"-"&LEFT(I$3,2),Data!$F:$F,"Number of Users",Data!$H:$H,"Non-Jordanian",Data!$I:$I,"") -> 89200 | J9: =SUMIFS(Data!$L:$L,Data!$B:$B,"cliq",Data!$K:$K,"native",Data!$J:$J,RIGHT(J$3,4)&"-"&LEFT(J$3,2),Data!$F:$F,"Number of Users",Data!$H:$H,"Non-Jordanian",Data!$I:$I,"") -> 94500
A10: Nationality | B10: Non-Jordanian (% of users) | C10: =C$9/(C$9+C$7) -> 0.035369775 | D10: =D$9/(D$9+D$7) -> 0.036505087 | E10: =E$9/(E$9+E$7) -> 0.037703995 | F10: =F$9/(F$9+F$7) -> 0.038154958 | G10: =G$9/(G$9+G$7) -> 0.038844622 | H10: =H$9/(H$9+H$7) -> 0.039548023 | I10: =I$9/(I$9+I$7) -> 0.040194665 | J10: =J$9/(J$9+J$7) -> 0.040829553
A11: USERS BY GENDER
A12: Gender | B12: Male (count) | C12: =SUMIFS(Data!$L:$L,Data!$B:$B,"cliq",Data!$K:$K,"native",Data!$J:$J,RIGHT(C$3,4)&"-"&LEFT(C$3,2),Data!$F:$F,"Number of Users",Data!$H:$H,"Male",Data!$I:$I,"") -> 973400 | D12: =SUMIFS(Data!$L:$L,Data!$B:$B,"cliq",Data!$K:$K,"native",Data!$J:$J,RIGHT(D$3,4)&"-"&LEFT(D$3,2),Data!$F:$F,"Number of Users",Data!$H:$H,"Male",Data!$I:$I,"") -> 1040000 | E12: =SUMIFS(Data!$L:$L,Data!$B:$B,"cliq",Data!$K:$K,"native",Data!$J:$J,RIGHT(E$3,4)&"-"&LEFT(E$3,2),Data!$F:$F,"Number of Users",Data!$H:$H,"Male",Data!$I:$I,"") -> 1110000 | F12: =SUMIFS(Data!$L:$L,Data!$B:$B,"cliq",Data!$K:$K,"native",Data!$J:$J,RIGHT(F$3,4)&"-"&LEFT(F$3,2),Data!$F:$F,"Number of Users",Data!$H:$H,"Male",Data!$I:$I,"") -> 1160000 | G12: =SUMIFS(Data!$L:$L,Data!$B:$B,"cliq",Data!$K:$K,"native",Data!$J:$J,RIGHT(G$3,4)&"-"&LEFT(G$3,2),Data!$F:$F,"Number of Users",Data!$H:$H,"Male",Data!$I:$I,"") -> 1240000 | H12: =SUMIFS(Data!$L:$L,Data!$B:$B,"cliq",Data!$K:$K,"native",Data!$J:$J,RIGHT(H$3,4)&"-"&LEFT(H$3,2),Data!$F:$F,"Number of Users",Data!$H:$H,"Male",Data!$I:$I,"") -> 1300000 | I12: =SUMIFS(Data!$L:$L,Data!$B:$B,"cliq",Data!$K:$K,"native",Data!$J:$J,RIGHT(I$3,4)&"-"&LEFT(I$3,2),Data!$F:$F,"Number of Users",Data!$H:$H,"Male",Data!$I:$I,"") -> 1350000 | J12: =SUMIFS(Data!$L:$L,Data!$B:$B,"cliq",Data!$K:$K,"native",Data!$J:$J,RIGHT(J$3,4)&"-"&LEFT(J$3,2),Data!$F:$F,"Number of Users",Data!$H:$H,"Male",Data!$I:$I,"") -> 1400000
A13: Gender | B13: Male (%) | C13: =C$12/(C$12+C$14) -> 0.64263551 | D13: =D$12/(D$12+D$14) -> 0.64074918 | E13: =E$12/(E$12+E$14) -> 0.64043388 | F13: =F$12/(F$12+F$14) -> 0.63694268 | G13: =G$12/(G$12+G$14) -> 0.63609316 | H13: =H$12/(H$12+H$14) -> 0.62996705 | I13: =I$12/(I$12+I$14) -> 0.62685736 | J13: =J$12/(J$12+J$14) -> 0.62474898
A14: Gender | B14: Female (count) | C14: =SUMIFS(Data!$L:$L,Data!$B:$B,"cliq",Data!$K:$K,"native",Data!$J:$J,RIGHT(C$3,4)&"-"&LEFT(C$3,2),Data!$F:$F,"Number of Users",Data!$H:$H,"Female",Data!$I:$I,"") -> 541300 | D14: =SUMIFS(Data!$L:$L,Data!$B:$B,"cliq",Data!$K:$K,"native",Data!$J:$J,RIGHT(D$3,4)&"-"&LEFT(D$3,2),Data!$F:$F,"Number of Users",Data!$H:$H,"Female",Data!$I:$I,"") -> 583100 | E14: =SUMIFS(Data!$L:$L,Data!$B:$B,"cliq",Data!$K:$K,"native",Data!$J:$J,RIGHT(E$3,4)&"-"&LEFT(E$3,2),Data!$F:$F,"Number of Users",Data!$H:$H,"Female",Data!$I:$I,"") -> 623200 | F14: =SUMIFS(Data!$L:$L,Data!$B:$B,"cliq",Data!$K:$K,"native",Data!$J:$J,RIGHT(F$3,4)&"-"&LEFT(F$3,2),Data!$F:$F,"Number of Users",Data!$H:$H,"Female",Data!$I:$I,"") -> 661200 | G14: =SUMIFS(Data!$L:$L,Data!$B:$B,"cliq",Data!$K:$K,"native",Data!$J:$J,RIGHT(G$3,4)&"-"&LEFT(G$3,2),Data!$F:$F,"Number of Users",Data!$H:$H,"Female",Data!$I:$I,"") -> 709400 | H14: =SUMIFS(Data!$L:$L,Data!$B:$B,"cliq",Data!$K:$K,"native",Data!$J:$J,RIGHT(H$3,4)&"-"&LEFT(H$3,2),Data!$F:$F,"Number of Users",Data!$H:$H,"Female",Data!$I:$I,"") -> 763600 | I14: =SUMIFS(Data!$L:$L,Data!$B:$B,"cliq",Data!$K:$K,"native",Data!$J:$J,RIGHT(I$3,4)&"-"&LEFT(I$3,2),Data!$F:$F,"Number of Users",Data!$H:$H,"Female",Data!$I:$I,"") -> 803600 | J14: =SUMIFS(Data!$L:$L,Data!$B:$B,"cliq",Data!$K:$K,"native",Data!$J:$J,RIGHT(J$3,4)&"-"&LEFT(J$3,2),Data!$F:$F,"Number of Users",Data!$H:$H,"Female",Data!$I:$I,"") -> 840900
A15: Gender | B15: Female (%) | C15: =C$14/(C$14+C$12) -> 0.35736449 | D15: =D$14/(D$14+D$12) -> 0.35925082 | E15: =E$14/(E$14+E$12) -> 0.35956612 | F15: =F$14/(F$14+F$12) -> 0.36305732 | G15: =G$14/(G$14+G$12) -> 0.36390684 | H15: =H$14/(H$14+H$12) -> 0.37003295 | I15: =I$14/(I$14+I$12) -> 0.37314264 | J15: =J$14/(J$14+J$12) -> 0.37525102
A16: USERS BY AGE BRACKET (count)
A17: Age | B17: <18 | C17: =SUMIFS(Data!$L:$L,Data!$B:$B,"cliq",Data!$K:$K,"native",Data!$J:$J,RIGHT(C$3,4)&"-"&LEFT(C$3,2),Data!$F:$F,"Number of Users",Data!$H:$H,"=<18",Data!$I:$I,"") -> 5800 | D17: =SUMIFS(Data!$L:$L,Data!$B:$B,"cliq",Data!$K:$K,"native",Data!$J:$J,RIGHT(D$3,4)&"-"&LEFT(D$3,2),Data!$F:$F,"Number of Users",Data!$H:$H,"=<18",Data!$I:$I,"") -> 6200 | E17: =SUMIFS(Data!$L:$L,Data!$B:$B,"cliq",Data!$K:$K,"native",Data!$J:$J,RIGHT(E$3,4)&"-"&LEFT(E$3,2),Data!$F:$F,"Number of Users",Data!$H:$H,"=<18",Data!$I:$I,"") -> 6700 | F17: =SUMIFS(Data!$L:$L,Data!$B:$B,"cliq",Data!$K:$K,"native",Data!$J:$J,RIGHT(F$3,4)&"-"&LEFT(F$3,2),Data!$F:$F,"Number of Users",Data!$H:$H,"=<18",Data!$I:$I,"") -> 8600 | G17: =SUMIFS(Data!$L:$L,Data!$B:$B,"cliq",Data!$K:$K,"native",Data!$J:$J,RIGHT(G$3,4)&"-"&LEFT(G$3,2),Data!$F:$F,"Number of Users",Data!$H:$H,"=<18",Data!$I:$I,"") -> 9200 | H17: =SUMIFS(Data!$L:$L,Data!$B:$B,"cliq",Data!$K:$K,"native",Data!$J:$J,RIGHT(H$3,4)&"-"&LEFT(H$3,2),Data!$F:$F,"Number of Users",Data!$H:$H,"=<18",Data!$I:$I,"") -> 9700 | I17: =SUMIFS(Data!$L:$L,Data!$B:$B,"cliq",Data!$K:$K,"native",Data!$J:$J,RIGHT(I$3,4)&"-"&LEFT(I$3,2),Data!$F:$F,"Number of Users",Data!$H:$H,"=<18",Data!$I:$I,"") -> 10400 | J17: =SUMIFS(Data!$L:$L,Data!$B:$B,"cliq",Data!$K:$K,"native",Data!$J:$J,RIGHT(J$3,4)&"-"&LEFT(J$3,2),Data!$F:$F,"Number of Users",Data!$H:$H,"=<18",Data!$I:$I,"") -> 11200
A18: Age | B18: 18-30 | C18: =SUMIFS(Data!$L:$L,Data!$B:$B,"cliq",Data!$K:$K,"native",Data!$J:$J,RIGHT(C$3,4)&"-"&LEFT(C$3,2),Data!$F:$F,"Number of Users",Data!$H:$H,"18-30",Data!$I:$I,"") -> 591000 | D18: =SUMIFS(Data!$L:$L,Data!$B:$B,"cliq",Data!$K:$K,"native",Data!$J:$J,RIGHT(D$3,4)&"-"&LEFT(D$3,2),Data!$F:$F,"Number of Users",Data!$H:$H,"18-30",Data!$I:$I,"") -> 626000 | E18: =SUMIFS(Data!$L:$L,Data!$B:$B,"cliq",Data!$K:$K,"native",Data!$J:$J,RIGHT(E$3,4)&"-"&LEFT(E$3,2),Data!$F:$F,"Number of Users",Data!$H:$H,"18-30",Data!$I:$I,"") -> 657000 | F18: =SUMIFS(Data!$L:$L,Data!$B:$B,"cliq",Data!$K:$K,"native",Data!$J:$J,RIGHT(F$3,4)&"-"&LEFT(F$3,2),Data!$F:$F,"Number of Users",Data!$H:$H,"18-30",Data!$I:$I,"") -> 684600 | G18: =SUMIFS(Data!$L:$L,Data!$B:$B,"cliq",Data!$K:$K,"native",Data!$J:$J,RIGHT(G$3,4)&"-"&LEFT(G$3,2),Data!$F:$F,"Number of Users",Data!$H:$H,"18-30",Data!$I:$I,"") -> 729700 | H18: =SUMIFS(Data!$L:$L,Data!$B:$B,"cliq",Data!$K:$K,"native",Data!$J:$J,RIGHT(H$3,4)&"-"&LEFT(H$3,2),Data!$F:$F,"Number of Users",Data!$H:$H,"18-30",Data!$I:$I,"") -> 775500 | I18: =SUMIFS(Data!$L:$L,Data!$B:$B,"cliq",Data!$K:$K,"native",Data!$J:$J,RIGHT(I$3,4)&"-"&LEFT(I$3,2),Data!$F:$F,"Number of Users",Data!$H:$H,"18-30",Data!$I:$I,"") -> 795100 | J18: =SUMIFS(Data!$L:$L,Data!$B:$B,"cliq",Data!$K:$K,"native",Data!$J:$J,RIGHT(J$3,4)&"-"&LEFT(J$3,2),Data!$F:$F,"Number of Users",Data!$H:$H,"18-30",Data!$I:$I,"") -> 816500
A19: Age | B19: 31-40 | C19: =SUMIFS(Data!$L:$L,Data!$B:$B,"cliq",Data!$K:$K,"native",Data!$J:$J,RIGHT(C$3,4)&"-"&LEFT(C$3,2),Data!$F:$F,"Number of Users",Data!$H:$H,"31-40",Data!$I:$I,"") -> 409200 | D19: =SUMIFS(Data!$L:$L,Data!$B:$B,"cliq",Data!$K:$K,"native",Data!$J:$J,RIGHT(D$3,4)&"-"&LEFT(D$3,2),Data!$F:$F,"Number of Users",Data!$H:$H,"31-40",Data!$I:$I,"") -> 437900 | E19: =SUMIFS(Data!$L:$L,Data!$B:$B,"cliq",Data!$K:$K,"native",Data!$J:$J,RIGHT(E$3,4)&"-"&LEFT(E$3,2),Data!$F:$F,"Number of Users",Data!$H:$H,"31-40",Data!$I:$I,"") -> 465900 | F19: =SUMIFS(Data!$L:$L,Data!$B:$B,"cliq",Data!$K:$K,"native",Data!$J:$J,RIGHT(F$3,4)&"-"&LEFT(F$3,2),Data!$F:$F,"Number of Users",Data!$H:$H,"31-40",Data!$I:$I,"") -> 490000 | G19: =SUMIFS(Data!$L:$L,Data!$B:$B,"cliq",Data!$K:$K,"native",Data!$J:$J,RIGHT(G$3,4)&"-"&LEFT(G$3,2),Data!$F:$F,"Number of Users",Data!$H:$H,"31-40",Data!$I:$I,"") -> 516000 | H19: =SUMIFS(Data!$L:$L,Data!$B:$B,"cliq",Data!$K:$K,"native",Data!$J:$J,RIGHT(H$3,4)&"-"&LEFT(H$3,2),Data!$F:$F,"Number of Users",Data!$H:$H,"31-40",Data!$I:$I,"") -> 542000 | I19: =SUMIFS(Data!$L:$L,Data!$B:$B,"cliq",Data!$K:$K,"native",Data!$J:$J,RIGHT(I$3,4)&"-"&LEFT(I$3,2),Data!$F:$F,"Number of Users",Data!$H:$H,"31-40",Data!$I:$I,"") -> 567000 | J19: =SUMIFS(Data!$L:$L,Data!$B:$B,"cliq",Data!$K:$K,"native",Data!$J:$J,RIGHT(J$3,4)&"-"&LEFT(J$3,2),Data!$F:$F,"Number of Users",Data!$H:$H,"31-40",Data!$I:$I,"") -> 589000
A20: Age | B20: 41-50 | C20: =SUMIFS(Data!$L:$L,Data!$B:$B,"cliq",Data!$K:$K,"native",Data!$J:$J,RIGHT(C$3,4)&"-"&LEFT(C$3,2),Data!$F:$F,"Number of Users",Data!$H:$H,"41-50",Data!$I:$I,"") -> 267100 | D20: =SUMIFS(Data!$L:$L,Data!$B:$B,"cliq",Data!$K:$K,"native",Data!$J:$J,RIGHT(D$3,4)&"-"&LEFT(D$3,2),Data!$F:$F,"Number of Users",Data!$H:$H,"41-50",Data!$I:$I,"") -> 289300 | E20: =SUMIFS(Data!$L:$L,Data!$B:$B,"cliq",Data!$K:$K,"native",Data!$J:$J,RIGHT(E$3,4)&"-"&LEFT(E$3,2),Data!$F:$F,"Number of Users",Data!$H:$H,"41-50",Data!$I:$I,"") -> 311700 | F20: =SUMIFS(Data!$L:$L,Data!$B:$B,"cliq",Data!$K:$K,"native",Data!$J:$J,RIGHT(F$3,4)&"-"&LEFT(F$3,2),Data!$F:$F,"Number of Users",Data!$H:$H,"41-50",Data!$I:$I,"") -> 331600 | G20: =SUMIFS(Data!$L:$L,Data!$B:$B,"cliq",Data!$K:$K,"native",Data!$J:$J,RIGHT(G$3,4)&"-"&LEFT(G$3,2),Data!$F:$F,"Number of Users",Data!$H:$H,"41-50",Data!$I:$I,"") -> 354300 | H20: =SUMIFS(Data!$L:$L,Data!$B:$B,"cliq",Data!$K:$K,"native",Data!$J:$J,RIGHT(H$3,4)&"-"&LEFT(H$3,2),Data!$F:$F,"Number of Users",Data!$H:$H,"41-50",Data!$I:$I,"") -> 375400 | I20: =SUMIFS(Data!$L:$L,Data!$B:$B,"cliq",Data!$K:$K,"native",Data!$J:$J,RIGHT(I$3,4)&"-"&LEFT(I$3,2),Data!$F:$F,"Number of Users",Data!$H:$H,"41-50",Data!$I:$I,"") -> 397000 | J20: =SUMIFS(Data!$L:$L,Data!$B:$B,"cliq",Data!$K:$K,"native",Data!$J:$J,RIGHT(J$3,4)&"-"&LEFT(J$3,2),Data!$F:$F,"Number of Users",Data!$H:$H,"41-50",Data!$I:$I,"") -> 415300
A21: Age | B21: 51-60 | C21: =SUMIFS(Data!$L:$L,Data!$B:$B,"cliq",Data!$K:$K,"native",Data!$J:$J,RIGHT(C$3,4)&"-"&LEFT(C$3,2),Data!$F:$F,"Number of Users",Data!$H:$H,"51-60",Data!$I:$I,"") -> 162500 | D21: =SUMIFS(Data!$L:$L,Data!$B:$B,"cliq",Data!$K:$K,"native",Data!$J:$J,RIGHT(D$3,4)&"-"&LEFT(D$3,2),Data!$F:$F,"Number of Users",Data!$H:$H,"51-60",Data!$I:$I,"") -> 176600 | E21: =SUMIFS(Data!$L:$L,Data!$B:$B,"cliq",Data!$K:$K,"native",Data!$J:$J,RIGHT(E$3,4)&"-"&LEFT(E$3,2),Data!$F:$F,"Number of Users",Data!$H:$H,"51-60",Data!$I:$I,"") -> 190700 | F21: =SUMIFS(Data!$L:$L,Data!$B:$B,"cliq",Data!$K:$K,"native",Data!$J:$J,RIGHT(F$3,4)&"-"&LEFT(F$3,2),Data!$F:$F,"Number of Users",Data!$H:$H,"51-60",Data!$I:$I,"") -> 203500 | G21: =SUMIFS(Data!$L:$L,Data!$B:$B,"cliq",Data!$K:$K,"native",Data!$J:$J,RIGHT(G$3,4)&"-"&LEFT(G$3,2),Data!$F:$F,"Number of Users",Data!$H:$H,"51-60",Data!$I:$I,"") -> 218100 | H21: =SUMIFS(Data!$L:$L,Data!$B:$B,"cliq",Data!$K:$K,"native",Data!$J:$J,RIGHT(H$3,4)&"-"&LEFT(H$3,2),Data!$F:$F,"Number of Users",Data!$H:$H,"51-60",Data!$I:$I,"") -> 232200 | I21: =SUMIFS(Data!$L:$L,Data!$B:$B,"cliq",Data!$K:$K,"native",Data!$J:$J,RIGHT(I$3,4)&"-"&LEFT(I$3,2),Data!$F:$F,"Number of Users",Data!$H:$H,"51-60",Data!$I:$I,"") -> 246200 | J21: =SUMIFS(Data!$L:$L,Data!$B:$B,"cliq",Data!$K:$K,"native",Data!$J:$J,RIGHT(J$3,4)&"-"&LEFT(J$3,2),Data!$F:$F,"Number of Users",Data!$H:$H,"51-60",Data!$I:$I,"") -> 258400
A22: Age | B22: 61-70 | C22: =SUMIFS(Data!$L:$L,Data!$B:$B,"cliq",Data!$K:$K,"native",Data!$J:$J,RIGHT(C$3,4)&"-"&LEFT(C$3,2),Data!$F:$F,"Number of Users",Data!$H:$H,"61-70",Data!$I:$I,"") -> 71100 | D22: =SUMIFS(Data!$L:$L,Data!$B:$B,"cliq",Data!$K:$K,"native",Data!$J:$J,RIGHT(D$3,4)&"-"&LEFT(D$3,2),Data!$F:$F,"Number of Users",Data!$H:$H,"61-70",Data!$I:$I,"") -> 78100 | E22: =SUMIFS(Data!$L:$L,Data!$B:$B,"cliq",Data!$K:$K,"native",Data!$J:$J,RIGHT(E$3,4)&"-"&LEFT(E$3,2),Data!$F:$F,"Number of Users",Data!$H:$H,"61-70",Data!$I:$I,"") -> 85500 | F22: =SUMIFS(Data!$L:$L,Data!$B:$B,"cliq",Data!$K:$K,"native",Data!$J:$J,RIGHT(F$3,4)&"-"&LEFT(F$3,2),Data!$F:$F,"Number of Users",Data!$H:$H,"61-70",Data!$I:$I,"") -> 92500 | G22: =SUMIFS(Data!$L:$L,Data!$B:$B,"cliq",Data!$K:$K,"native",Data!$J:$J,RIGHT(G$3,4)&"-"&LEFT(G$3,2),Data!$F:$F,"Number of Users",Data!$H:$H,"61-70",Data!$I:$I,"") -> 99800 | H22: =SUMIFS(Data!$L:$L,Data!$B:$B,"cliq",Data!$K:$K,"native",Data!$J:$J,RIGHT(H$3,4)&"-"&LEFT(H$3,2),Data!$F:$F,"Number of Users",Data!$H:$H,"61-70",Data!$I:$I,"") -> 107100 | I22: =SUMIFS(Data!$L:$L,Data!$B:$B,"cliq",Data!$K:$K,"native",Data!$J:$J,RIGHT(I$3,4)&"-"&LEFT(I$3,2),Data!$F:$F,"Number of Users",Data!$H:$H,"61-70",Data!$I:$I,"") -> 115500 | J22: =SUMIFS(Data!$L:$L,Data!$B:$B,"cliq",Data!$K:$K,"native",Data!$J:$J,RIGHT(J$3,4)&"-"&LEFT(J$3,2),Data!$F:$F,"Number of Users",Data!$H:$H,"61-70",Data!$I:$I,"") -> 122800
A23: Age | B23: 71-80 | C23: =SUMIFS(Data!$L:$L,Data!$B:$B,"cliq",Data!$K:$K,"native",Data!$J:$J,RIGHT(C$3,4)&"-"&LEFT(C$3,2),Data!$F:$F,"Number of Users",Data!$H:$H,"71-80",Data!$I:$I,"") -> 18100 | D23: =SUMIFS(Data!$L:$L,Data!$B:$B,"cliq",Data!$K:$K,"native",Data!$J:$J,RIGHT(D$3,4)&"-"&LEFT(D$3,2),Data!$F:$F,"Number of Users",Data!$H:$H,"71-80",Data!$I:$I,"") -> 20100 | E23: =SUMIFS(Data!$L:$L,Data!$B:$B,"cliq",Data!$K:$K,"native",Data!$J:$J,RIGHT(E$3,4)&"-"&LEFT(E$3,2),Data!$F:$F,"Number of Users",Data!$H:$H,"71-80",Data!$I:$I,"") -> 22100 | F23: =SUMIFS(Data!$L:$L,Data!$B:$B,"cliq",Data!$K:$K,"native",Data!$J:$J,RIGHT(F$3,4)&"-"&LEFT(F$3,2),Data!$F:$F,"Number of Users",Data!$H:$H,"71-80",Data!$I:$I,"") -> 24200 | G23: =SUMIFS(Data!$L:$L,Data!$B:$B,"cliq",Data!$K:$K,"native",Data!$J:$J,RIGHT(G$3,4)&"-"&LEFT(G$3,2),Data!$F:$F,"Number of Users",Data!$H:$H,"71-80",Data!$I:$I,"") -> 26500 | H23: =SUMIFS(Data!$L:$L,Data!$B:$B,"cliq",Data!$K:$K,"native",Data!$J:$J,RIGHT(H$3,4)&"-"&LEFT(H$3,2),Data!$F:$F,"Number of Users",Data!$H:$H,"71-80",Data!$I:$I,"") -> 28800 | I23: =SUMIFS(Data!$L:$L,Data!$B:$B,"cliq",Data!$K:$K,"native",Data!$J:$J,RIGHT(I$3,4)&"-"&LEFT(I$3,2),Data!$F:$F,"Number of Users",Data!$H:$H,"71-80",Data!$I:$I,"") -> 31500 | J23: =SUMIFS(Data!$L:$L,Data!$B:$B,"cliq",Data!$K:$K,"native",Data!$J:$J,RIGHT(J$3,4)&"-"&LEFT(J$3,2),Data!$F:$F,"Number of Users",Data!$H:$H,"71-80",Data!$I:$I,"") -> 34000
